Workbook

Sheet 사업관리 일정계획
A1: 구분 | B1: 월별 | D1: 8월 (M) | H1: 9월 (M+1) | P1: 10월 (M+2) | X1: 11월 (M+3) | AG1: 비고
B2: 주별 | C2: W1 | E2: W2 | G2: W1 | I2: W2 | K2: W3 | M2: W4 | O2: W1 | Q2: W2 | S2: W3 | U2: W4 | W2: W1 | Y2: W2 | AA2: W3 | AC2: W4 | AE2: W5
B3: 일별 | C3: 2023-08-05~ | E3: 2023-08-12~ | G3: 2023-08-19~ | I3: 2023-09-02~ | K3: 2023-09-09~ | M3: 2023-09-19~ | O3: 2023-09-30~ | Q3: 2023-10-07~ | S3: 2023-10-14~ | U3: 2023-10-21~ | W3: 2024-10-28~ | Y3: 2024-11-04~ | AA3: 2024-11-11~ | AC3: 202411-18~ | AE3: 2024-11-25~
B4: 계획/실적 | C4: 계획(누적) | D4: 실적(누적) | E4: 계획(누적) | F4: 실적(누적) | G4: 계획(누적) | H4: 실적(누적) | I4: 계획(누적) | J4: 실적(누적) | K4: 계획(누적) | L4: 실적(누적) | M4: 계획(누적) | N4: 실적(누적) | O4: 계획(누적) | P4: 실적(누적) | Q4: 계획(누적) | R4: 실적(누적) | S4: 계획(누적) | T4: 실적(누적) | U4: 계획(누적) | V4: 실적(누적) | W4: 계획(누적) | X4: 실적(누적) | Y4: 계획(누적) | Z4: 실적(누적) | AA4: 계획(누적) | AB4: 실적(누적) | AC4: 계획(누적) | AD4: 실적(누적) | AE4: 계획(누적) | AF4: 실적(누적)
A5: 주관기관 보고일정 | B5: 단계별 보고 | C5: 착수보고 | E5: - | G5: - | I5: - | K5: - | M5: - | O5: - | Q5: - | S5: - | U5: - | W5: 중간보고 | Y5: - | AA5: - | AC5: - | AE5: - | AG5: -
B6: 정기보고 | C6: - | E6: 주간보고 | G6: 주간보고 | I6: 주간보고 | K6: 주간보고 | M6: 주간보고 | O6: 주간보고 | Q6: 주간보고 | S6: 주간보고 | U6: 주간보고 | W6: 주간보고 | Y6: 주간보고 | AA6: 주간보고 | AC6: 주간보고 | AE6: 주간보고
A7: 인터뷰 일정수립 | B7: 참여대학별 인터뷰진행 | C7: 인터뷰진행 | E7: 인터뷰진행 | G7: 인터뷰진행 | I7: 인터뷰진행 | K7: - | M7: - | O7: - | Q7: - | S7: - | U7: - | W7: - | Y7: - | AA7: - | AC7: - | AE7: - | AG7: * 요구사항 인터뷰 * 건축법관련 데이터 인터뷰 * 기타 요구사항 인터뷰
A8: 시스템 기능별 개발 일정 | B8: 모델링 | C8: =SUM('기능 개발 WBS'!$N$5:$N$13)/COUNTA('기능 개발 WBS'!$F$5:$F$13) -> 0 | D8: =SUM('기능 개발 WBS'!$O$5:$O$13)/COUNTA('기능 개발 WBS'!$F$5:$F$13) -> 0 | E8: =SUM('기능 개발 WBS'!$V$5:$V$13)/COUNTA('기능 개발 WBS'!$F$5:$F$13) -> 0 | F8: =SUM('기능 개발 WBS'!$W$5:$W$13)/COUNTA('기능 개발 WBS'!$F$5:$F$13) -> 0 | G8: =SUM('기능 개발 WBS'!$AD$5:$AD$13)/COUNTA('기능 개발 WBS'!$F$5:$F$13) -> 0 | H8: =SUM('기능 개발 WBS'!$AE$5:$AE$13)/COUNTA('기능 개발 WBS'!$F$5:$F$13) -> 0 | I8: =SUM('기능 개발 WBS'!$AL$5:$AL$13)/COUNTA('기능 개발 WBS'!$F$5:$F$13) -> 0 | J8: =SUM('기능 개발 WBS'!$AM$5:$AM$13)/COUNTA('기능 개발 WBS'!$F$5:$F$13) -> 0 | K8: =SUM('기능 개발 WBS'!$AT$5:$AT$13)/COUNTA('기능 개발 WBS'!$F$5:$F$13) -> 0 | L8: =SUM('기능 개발 WBS'!$AU$5:$AU$13)/COUNTA('기능 개발 WBS'!$F$5:$F$13) -> 0 | M8: =SUM('기능 개발 WBS'!$BB$5:$BB$13)/COUNTA('기능 개발 WBS'!$F$5:$F$13) -> 0 | N8: =SUM('기능 개발 WBS'!$BC$5:$BC$13)/COUNTA('기능 개발 WBS'!$F$5:$F$13) -> 0 | O8: =SUM('기능 개발 WBS'!$BJ$5:$BJ$13)/COUNTA('기능 개발 WBS'!$F$5:$F$13) -> 0 | P8: =SUM('기능 개발 WBS'!$BK$5:$BK$13)/COUNTA('기능 개발 WBS'!$F$5:$F$13) -> 0 | Q8: =SUM('기능 개발 WBS'!$BR$5:$BR$13)/COUNTA('기능 개발 WBS'!$F$5:$F$13) -> 0 | R8: =SUM('기능 개발 WBS'!$BS$5:$BS$13)/COUNTA('기능 개발 WBS'!$F$5:$F$13) -> 0 | S8: =SUM('기능 개발 WBS'!$BZ$5:$BZ$13)/COUNTA('기능 개발 WBS'!$F$5:$F$13) -> 0 | T8: =SUM('기능 개발 WBS'!$CA$5:$CA$13)/COUNTA('기능 개발 WBS'!$F$5:$F$13) -> 0 | U8: =SUM('기능 개발 WBS'!$CH$5:$CH$13)/COUNTA('기능 개발 WBS'!$F$5:$F$13) -> 0 | V8: =SUM('기능 개발 WBS'!$CI$5:$CI$13)/COUNTA('기능 개발 WBS'!$F$5:$F$13) -> 0 | W8: =SUM('기능 개발 WBS'!$CP$5:$CP$13)/COUNTA('기능 개발 WBS'!$F$5:$F$13) -> 0 | X8: =SUM('기능 개발 WBS'!$CQ$5:$CQ$13)/COUNTA('기능 개발 WBS'!$F$5:$F$13) -> 0 | Y8: =SUM('기능 개발 WBS'!$CX$5:$CX$13)/COUNTA('기능 개발 WBS'!$F$5:$F$13) -> 0 | Z8: =SUM('기능 개발 WBS'!$CY$5:$CY$13)/COUNTA('기능 개발 WBS'!$F$5:$F$13) -> 0 | AA8: =SUM('기능 개발 WBS'!$DF$5:$DF$13)/COUNTA('기능 개발 WBS'!$F$5:$F$13) -> 0 | AB8: =SUM('기능 개발 WBS'!$DG$5:$DG$13)/COUNTA('기능 개발 WBS'!$F$5:$F$13) -> 0 | AC8: =SUM('기능 개발 WBS'!$DN$5:$DN$13)/COUNTA('기능 개발 WBS'!$F$5:$F$13) -> 0 | AD8: =SUM('기능 개발 WBS'!$DO$5:$DO$13)/COUNTA('기능 개발 WBS'!$F$5:$F$13) -> 0 | AE8: =SUM('기능 개발 WBS'!#REF!)/COUNTA('기능 개발 WBS'!$F$5:$F$13) -> #REF! | AF8: =SUM('기능 개발 WBS'!#REF!)/COUNTA('기능 개발 WBS'!$F$5:$F$13) -> #REF! | AG8: * 기능별 개발 세부일정은 WBS에 기반한 일정수립
B9: VR메타버스 | C9: =SUM('기능 개발 WBS'!$N$23:$N$28)/COUNTA('기능 개발 WBS'!$F$23:$F$28) -> 0 | D9: =SUM('기능 개발 WBS'!$O$23:$O$28)/COUNTA('기능 개발 WBS'!$F$23:$F$28) -> 0 | E9: =SUM('기능 개발 WBS'!$V$23:$V$28)/COUNTA('기능 개발 WBS'!$F$23:$F$28) -> 0 | F9: =SUM('기능 개발 WBS'!$W$23:$W$28)/COUNTA('기능 개발 WBS'!$F$23:$F$28) -> 0 | G9: =SUM('기능 개발 WBS'!$AD$23:$AD$28)/COUNTA('기능 개발 WBS'!$F$23:$F$28) -> 0 | H9: =SUM('기능 개발 WBS'!$AE$23:$AE$28)/COUNTA('기능 개발 WBS'!$F$23:$F$28) -> 0 | I9: =SUM('기능 개발 WBS'!$AL$23:$AL$28)/COUNTA('기능 개발 WBS'!$F$23:$F$28) -> 0 | J9: =SUM('기능 개발 WBS'!$AM$23:$AM$28)/COUNTA('기능 개발 WBS'!$F$23:$F$28) -> 0 | K9: =SUM('기능 개발 WBS'!$AT$23:$AT$28)/COUNTA('기능 개발 WBS'!$F$23:$F$28) -> 0 | L9: =SUM('기능 개발 WBS'!$AU$23:$AU$28)/COUNTA('기능 개발 WBS'!$F$23:$F$28) -> 0 | M9: =SUM('기능 개발 WBS'!$BB$23:$BB$28)/COUNTA('기능 개발 WBS'!$F$23:$F$28) -> 0 | N9: =SUM('기능 개발 WBS'!$BC$23:$BC$28)/COUNTA('기능 개발 WBS'!$F$23:$F$28) -> 0 | O9: =SUM('기능 개발 WBS'!$BJ$23:$BJ$28)/COUNTA('기능 개발 WBS'!$F$23:$F$28) -> 0 | P9: =SUM('기능 개발 WBS'!$BK$23:$BK$28)/COUNTA('기능 개발 WBS'!$F$23:$F$28) -> 0 | Q9: =SUM('기능 개발 WBS'!$BR$23:$BR$28)/COUNTA('기능 개발 WBS'!$F$23:$F$28) -> 0 | R9: =SUM('기능 개발 WBS'!$BS$23:$BS$28)/COUNTA('기능 개발 WBS'!$F$23:$F$28) -> 0 | S9: =SUM('기능 개발 WBS'!$BZ$23:$BZ$28)/COUNTA('기능 개발 WBS'!$F$23:$F$28) -> 0 | T9: =SUM('기능 개발 WBS'!$CA$23:$CA$28)/COUNTA('기능 개발 WBS'!$F$23:$F$28) -> 0 | U9: =SUM('기능 개발 WBS'!$CH$23:$CH$28)/COUNTA('기능 개발 WBS'!$F$23:$F$28) -> 0 | V9: =SUM('기능 개발 WBS'!$CI$23:$CI$28)/COUNTA('기능 개발 WBS'!$F$23:$F$28) -> 0 | W9: =SUM('기능 개발 WBS'!$CP$23:$CP$28)/COUNTA('기능 개발 WBS'!$F$23:$F$28) -> 0 | X9: =SUM('기능 개발 WBS'!$CQ$23:$CQ$28)/COUNTA('기능 개발 WBS'!$F$23:$F$28) -> 0 | Y9: =SUM('기능 개발 WBS'!$CX$23:$CX$28)/COUNTA('기능 개발 WBS'!$F$23:$F$28) -> 0 | Z9: =SUM('기능 개발 WBS'!$CY$23:$CY$28)/COUNTA('기능 개발 WBS'!$F$23:$F$28) -> 0 | AA9: =SUM('기능 개발 WBS'!$DF$23:$DF$28)/COUNTA('기능 개발 WBS'!$F$23:$F$28) -> 0 | AB9: =SUM('기능 개발 WBS'!$DG$23:$DG$28)/COUNTA('기능 개발 WBS'!$F$23:$F$28) -> 0 | AC9: =SUM('기능 개발 WBS'!$DN$23:$DN$28)/COUNTA('기능 개발 WBS'!$F$23:$F$28) -> 0 | AD9: =SUM('기능 개발 WBS'!$DO$23:$DO$28)/COUNTA('기능 개발 WBS'!$F$23:$F$28) -> 0 | AE9: =SUM('기능 개발 WBS'!#REF!)/COUNTA('기능 개발 WBS'!$F$23:$F$28) -> #REF! | AF9: =SUM('기능 개발 WBS'!#REF!)/COUNTA('기능 개발 WBS'!$F$23:$F$28) -> #REF!
B10: 가상공간 커뮤니케이션 | C10: =SUM('기능 개발 WBS'!$N$29:$N$31)/COUNTA('기능 개발 WBS'!$F$29:$F$31) -> 0 | D10: =SUM('기능 개발 WBS'!$O$29:$O$31)/COUNTA('기능 개발 WBS'!$F$29:$F$31) -> 0 | E10: =SUM('기능 개발 WBS'!$V$29:$V$31)/COUNTA('기능 개발 WBS'!$F$29:$F$31) -> 0 | F10: =SUM('기능 개발 WBS'!$W$29:$W$31)/COUNTA('기능 개발 WBS'!$F$29:$F$31) -> 0 | G10: =SUM('기능 개발 WBS'!$AD$29:$AD$31)/COUNTA('기능 개발 WBS'!$F$29:$F$31) -> 0 | H10: =SUM('기능 개발 WBS'!$AE$29:$AE$31)/COUNTA('기능 개발 WBS'!$F$29:$F$31) -> 0 | I10: =SUM('기능 개발 WBS'!$AL$29:$AL$31)/COUNTA('기능 개발 WBS'!$F$29:$F$31) -> 0 | J10: =SUM('기능 개발 WBS'!$AM$29:$AM$31)/COUNTA('기능 개발 WBS'!$F$29:$F$31) -> 0 | K10: =SUM('기능 개발 WBS'!$AT$29:$AT$31)/COUNTA('기능 개발 WBS'!$F$29:$F$31) -> 0 | L10: =SUM('기능 개발 WBS'!$AU$29:$AU$31)/COUNTA('기능 개발 WBS'!$F$29:$F$31) -> 0 | M10: =SUM('기능 개발 WBS'!$BB$29:$BB$31)/COUNTA('기능 개발 WBS'!$F$29:$F$31) -> 0 | N10: =SUM('기능 개발 WBS'!$BC$29:$BC$31)/COUNTA('기능 개발 WBS'!$F$29:$F$31) -> 0 | O10: =SUM('기능 개발 WBS'!$BJ$29:$BJ$31)/COUNTA('기능 개발 WBS'!$F$29:$F$31) -> 0 | P10: =SUM('기능 개발 WBS'!$BK$29:$BK$31)/COUNTA('기능 개발 WBS'!$F$29:$F$31) -> 0 | Q10: =SUM('기능 개발 WBS'!$BR$29:$BR$31)/COUNTA('기능 개발 WBS'!$F$29:$F$31) -> 0 | R10: =SUM('기능 개발 WBS'!$BS$29:$BS$31)/COUNTA('기능 개발 WBS'!$F$29:$F$31) -> 0 | S10: =SUM('기능 개발 WBS'!$BZ$29:$BZ$31)/COUNTA('기능 개발 WBS'!$F$29:$F$31) -> 0 | T10: =SUM('기능 개발 WBS'!$CA$29:$CA$31)/COUNTA('기능 개발 WBS'!$F$29:$F$31) -> 0 | U10: =SUM('기능 개발 WBS'!$CH$29:$CH$31)/COUNTA('기능 개발 WBS'!$F$29:$F$31) -> 0 | V10: =SUM('기능 개발 WBS'!$CI$29:$CI$31)/COUNTA('기능 개발 WBS'!$F$29:$F$31) -> 0 | W10: =SUM('기능 개발 WBS'!$CP$29:$CP$31)/COUNTA('기능 개발 WBS'!$F$29:$F$31) -> 0 | X10: =SUM('기능 개발 WBS'!$CQ$29:$CQ$31)/COUNTA('기능 개발 WBS'!$F$29:$F$31) -> 0 | Y10: =SUM('기능 개발 WBS'!$CX$29:$CX$31)/COUNTA('기능 개발 WBS'!$F$29:$F$31) -> 0 | Z10: =SUM('기능 개발 WBS'!$CY$29:$CY$31)/COUNTA('기능 개발 WBS'!$F$29:$F$31) -> 0 | AA10: =SUM('기능 개발 WBS'!$DF$29:$DF$31)/COUNTA('기능 개발 WBS'!$F$29:$F$31) -> 0 | AB10: =SUM('기능 개발 WBS'!$DG$29:$DG$31)/COUNTA('기능 개발 WBS'!$F$29:$F$31) -> 0 | AC10: =SUM('기능 개발 WBS'!$DN$29:$DN$31)/COUNTA('기능 개발 WBS'!$F$29:$F$31) -> 0 | AD10: =SUM('기능 개발 WBS'!$DO$29:$DO$31)/COUNTA('기능 개발 WBS'!$F$29:$F$31) -> 0 | AE10: =SUM('기능 개발 WBS'!#REF!)/COUNTA('기능 개발 WBS'!$F$29:$F$31) -> #REF! | AF10: =SUM('기능 개발 WBS'!#REF!)/COUNTA('기능 개발 WBS'!$F$29:$F$31) -> #REF!
B11: 건축정보데이터 | C11: =SUM('기능 개발 WBS'!$N$32:$N$37)/COUNTA('기능 개발 WBS'!$F$32:$F$37) -> 0 | D11: =SUM('기능 개발 WBS'!$O$32:$O$37)/COUNTA('기능 개발 WBS'!$F$32:$F$37) -> 0 | E11: =SUM('기능 개발 WBS'!$V$32:$V$37)/COUNTA('기능 개발 WBS'!$F$32:$F$37) -> 0 | F11: =SUM('기능 개발 WBS'!$W$32:$W$37)/COUNTA('기능 개발 WBS'!$F$32:$F$37) -> 0 | G11: =SUM('기능 개발 WBS'!$AD$32:$AD$37)/COUNTA('기능 개발 WBS'!$F$32:$F$37) -> 0 | H11: =SUM('기능 개발 WBS'!$AE$32:$AE$37)/COUNTA('기능 개발 WBS'!$F$32:$F$37) -> 0 | I11: =SUM('기능 개발 WBS'!$AL$32:$AL$37)/COUNTA('기능 개발 WBS'!$F$32:$F$37) -> 0 | J11: =SUM('기능 개발 WBS'!$AM$32:$AM$37)/COUNTA('기능 개발 WBS'!$F$32:$F$37) -> 0 | K11: =SUM('기능 개발 WBS'!$AT$32:$AT$37)/COUNTA('기능 개발 WBS'!$F$32:$F$37) -> 0 | L11: =SUM('기능 개발 WBS'!$AU$32:$AU$37)/COUNTA('기능 개발 WBS'!$F$32:$F$37) -> 0 | M11: =SUM('기능 개발 WBS'!$BB$32:$BB$37)/COUNTA('기능 개발 WBS'!$F$32:$F$37) -> 0 | N11: =SUM('기능 개발 WBS'!$BC$32:$BC$37)/COUNTA('기능 개발 WBS'!$F$32:$F$37) -> 0 | O11: =SUM('기능 개발 WBS'!$BJ$32:$BJ$37)/COUNTA('기능 개발 WBS'!$F$32:$F$37) -> 0 | P11: =SUM('기능 개발 WBS'!$BK$32:$BK$37)/COUNTA('기능 개발 WBS'!$F$32:$F$37) -> 0 | Q11: =SUM('기능 개발 WBS'!$BR$32:$BR$37)/COUNTA('기능 개발 WBS'!$F$32:$F$37) -> 0 | R11: =SUM('기능 개발 WBS'!$BS$32:$BS$37)/COUNTA('기능 개발 WBS'!$F$32:$F$37) -> 0 | S11: =SUM('기능 개발 WBS'!$BZ$32:$BZ$37)/COUNTA('기능 개발 WBS'!$F$32:$F$37) -> 0 | T11: =SUM('기능 개발 WBS'!$CA$32:$CA$37)/COUNTA('기능 개발 WBS'!$F$32:$F$37) -> 0 | U11: =SUM('기능 개발 WBS'!$CH$32:$CH$37)/COUNTA('기능 개발 WBS'!$F$32:$F$37) -> 0 | V11: =SUM('기능 개발 WBS'!$CI$32:$CI$37)/COUNTA('기능 개발 WBS'!$F$32:$F$37) -> 0 | W11: =SUM('기능 개발 WBS'!$CP$32:$CP$37)/COUNTA('기능 개발 WBS'!$F$32:$F$37) -> 0 | X11: =SUM('기능 개발 WBS'!$CQ$32:$CQ$37)/COUNTA('기능 개발 WBS'!$F$32:$F$37) -> 0 | Y11: =SUM('기능 개발 WBS'!$CX$32:$CX$37)/COUNTA('기능 개발 WBS'!$F$32:$F$37) -> 0 | Z11: =SUM('기능 개발 WBS'!$CY$32:$CY$37)/COUNTA('기능 개발 WBS'!$F$32:$F$37) -> 0 | AA11: =SUM('기능 개발 WBS'!$DF$32:$DF$37)/COUNTA('기능 개발 WBS'!$F$32:$F$37) -> 0 | AB11: =SUM('기능 개발 WBS'!$DG$32:$DG$37)/COUNTA('기능 개발 WBS'!$F$32:$F$37) -> 0 | AC11: =SUM('기능 개발 WBS'!$DN$32:$DN$37)/COUNTA('기능 개발 WBS'!$F$32:$F$37) -> 0 | AD11: =SUM('기능 개발 WBS'!$DO$32:$DO$37)/COUNTA('기능 개발 WBS'!$F$32:$F$37) -> 0 | AE11: =SUM('기능 개발 WBS'!#REF!)/COUNTA('기능 개발 WBS'!$F$32:$F$37) -> #REF! | AF11: =SUM('기능 개발 WBS'!#REF!)/COUNTA('기능 개발 WBS'!$F$32:$F$37) -> #REF!
B12: UI설계 및 연동데이터 시뮬레이션 | C12: =SUM('기능 개발 WBS'!#REF!)/COUNTA('기능 개발 WBS'!#REF!) -> #REF! | D12: =SUM('기능 개발 WBS'!#REF!)/COUNTA('기능 개발 WBS'!#REF!) -> #REF! | E12: =SUM('기능 개발 WBS'!#REF!)/COUNTA('기능 개발 WBS'!#REF!) -> #REF! | F12: =SUM('기능 개발 WBS'!#REF!)/COUNTA('기능 개발 WBS'!#REF!) -> #REF! | G12: =SUM('기능 개발 WBS'!#REF!)/COUNTA('기능 개발 WBS'!#REF!) -> #REF! | H12: =SUM('기능 개발 WBS'!#REF!)/COUNTA('기능 개발 WBS'!#REF!) -> #REF! | I12: =SUM('기능 개발 WBS'!#REF!)/COUNTA('기능 개발 WBS'!#REF!) -> #REF! | J12: =SUM('기능 개발 WBS'!#REF!)/COUNTA('기능 개발 WBS'!#REF!) -> #REF! | ... AF12: =SUM('기능 개발 WBS'!#REF!)/COUNTA('기능 개발 WBS'!#REF!) -> #REF! | AG12: * PoC 마감일에 맞추어 기능 테스트기간 확보

Sheet 기능 개발 WBS
A1: 부동산 플랫폼 PoC WBS
A3: 사업명 | B3: 대분류 | C3: 중분류 | D3: 기능별 분류 | E3: 기간 대비 개발우선순위 | F3: 과업 Task | G3: 목표량 | H3: 목표량(합) | I3: 누적 실적 | J3: 누적 진척율(%) | K3: 8월3주(8/19~) | S3: 8월4주(8/26~) | AA3: 9월1주(9/02~) | AI3: 9월2주(9/09~) | AQ3: 9월3주(9/19~) | AY3: 9월4주(9/30~) | BG3: 10월1주(10/07~) | BO3: 10월2주(10/14~) | BW3: 10월3주(10/21~) | CE3: 10월4주(10/28~) | CM3: 11월1주(11/04~) | CU3: 11월2주(11/11~) | DC3: 11월3주(11/18~) | DK3: 11월4주(11/25~)
K4: 목표량 | L4: 실적 | M4: 진척율(%) | N4: 누적(목) | O4: 누적(실) | P4: 누적(차) | Q4: 목표율(%) | R4: 누적율(%) | S4: 목표량 | T4: 실적 | U4: 진척율(%) | V4: 누적(목) | W4: 누적(실) | X4: 누적(차) | Y4: 목표율(%) | Z4: 누적율(%) | AA4: 목표량 | AB4: 실적 | AC4: 진척율(%) | AD4: 누적(목) | AE4: 누적(실) | AF4: 누적(차) | AG4: 목표율(%) | AH4: 누적율(%) | AI4: 목표량 | AJ4: 실적 | AK4: 진척율(%) | AL4: 누적(목) | AM4: 누적(실) | AN4: 누적(차) | AO4: 목표율(%) | AP4: 누적율(%) | AQ4: 목표량 | AR4: 실적 | AS4: 진척율(%) | AT4: 누적(목) | AU4: 누적(실) | AV4: 누적(차) | AW4: 목표율(%) | AX4: 누적율(%) | AY4: 목표량 | AZ4: 실적 | BA4: 진척율(%) | BB4: 누적(목) | BC4: 누적(실) | BD4: 누적(차) | BE4: 목표율(%) | BF4: 누적율(%) | BG4: 목표량 | BH4: 실적 | BI4: 진척율(%) | BJ4: 누적(목) | BK4: 누적(실) | BL4: 누적(차) | BM4: 목표율(%) | BN4: 누적율(%) | BO4: 목표량 | BP4: 실적 | BQ4: 진척율(%) | BR4: 누적(목) | BS4: 누적(실) | BT4: 누적(차) | BU4: 목표율(%) | BV4: 누적율(%) | BW4: 목표량 | BX4: 실적 | BY4: 진척율(%) | BZ4: 누적(목) | CA4: 누적(실) | CB4: 누적(차) | CC4: 목표율(%) | CD4: 누적율(%) | CE4: 목표량 | CF4: 실적 | CG4: 진척율(%) | CH4: 누적(목) | CI4: 누적(실) | CJ4: 누적(차) | CK4: 목표율(%) | CL4: 누적율(%) | CM4: 목표량 | CN4: 실적 | CO4: 진척율(%) | CP4: 누적(목) | CQ4: 누적(실) | CR4: 누적(차) | CS4: 목표율(%) | CT4: 누적율(%) | CU4: 목표량 | CV4: 실적 | CW4: 진척율(%) | CX4: 누적(목) | CY4: 누적(실) | CZ4: 누적(차) | DA4: 목표율(%) | DB4: 누적율(%) | DC4: 목표량 | DD4: 실적 | DE4: 진척율(%) | DF4: 누적(목) | DG4: 누적(실) | DH4: 누적(차) | DI4: 목표율(%) | DJ4: 누적율(%) | DK4: 목표량 | DL4: 실적 | DM4: 진척율(%) | DN4: 누적(목) | DO4: 누적(실) | DP4: 누적(차) | DQ4: 목표율(%) | DR4: 누적율(%)
A5: 부동산 메타버스 플랫폼 PoC | B5: 모델링 | C5: 레벨디자인 모델링 (지형 및 도시 인프라) | D5: 지적도 기반 지형모델링 | F5: 설계 | G5: 1 | H5: 1 | I5: =SUM(L5+T5+AB5+AJ5+AR5+AZ5+BH5+BP5+BX5+CF5+CN5+CV5+DD5+DL5+DT5+EB5+EJ5+ER5+EZ5+FI5+FR5+GB5+GL5+GV5+HF5+HP5+HZ5+IJ5+IT5+JD5+JN5+JX5+KH5+KR5+LB5+LL5+LV5+MF5+MP5+MZ5) -> 0 | J5: =IFERROR(IF((I5/H5)>=1,100%,(I5/H5)),0%) -> 0 | K5: 0 | L5: 0 | M5: =IFERROR(IF((L5/K5)>=1,100%,(L5/K5)),0%) -> 0 | N5: =+K5 -> 0 | O5: =+L5 -> 0 | P5: =O5-N5 -> 0 | Q5: =N5/$G5 -> 0 | R5: =O5/$G5 -> 0 | S5: 0 | T5: 0 | U5: =IFERROR(IF((T5/S5)>=1,100%,(T5/S5)),0%) -> 0 | V5: =N5+S5 -> 0 | W5: =O5+T5 -> 0 | X5: =W5-V5 -> 0 | Y5: =V5/$G5 -> 0 | Z5: =W5/$G5 -> 0 | AA5: 0 | AB5: 0 | AC5: =IFERROR(IF((AB5/AA5)>=1,100%,(AB5/AA5)),0%) -> 0 | AD5: =V5+AA5 -> 0 | AE5: =W5+AB5 -> 0 | AF5: =AE5-AD5 -> 0 | AG5: =AD5/$G5 -> 0 | AH5: =AE5/$G5 -> 0 | AI5: 0 | AJ5: 0 | AK5: =IFERROR(IF((AJ5/AI5)>=1,100%,(AJ5/AI5)),0%) -> 0 | AL5: =AD5+AI5 -> 0 | AM5: =AE5+AJ5 -> 0 | AN5: =AM5-AL5 -> 0 | AO5: =AL5/$G5 -> 0 | AP5: =AM5/$G5 -> 0 | AQ5: 0 | AR5: 0 | AS5: =IFERROR(IF((AR5/AQ5)>=1,100%,(AR5/AQ5)),0%) -> 0 | AT5: =AL5+AQ5 -> 0 | AU5: =AM5+AR5 -> 0 | AV5: =AU5-AT5 -> 0 | AW5: =AT5/$G5 -> 0 | AX5: =AU5/$G5 -> 0 | AY5: 0 | AZ5: 0 | BA5: =IFERROR(IF((AZ5/AY5)>=1,100%,(AZ5/AY5)),0%) -> 0 | BB5: =AT5+AY5 -> 0 | BC5: =AU5+AZ5 -> 0 | BD5: =BC5-BB5 -> 0 | BE5: =BB5/$G5 -> 0 | BF5: =BC5/$G5 -> 0 | BG5: 0 | BH5: 0 | BI5: =IFERROR(IF((BH5/BG5)>=1,100%,(BH5/BG5)),0%) -> 0 | BJ5: =BB5+BG5 -> 0 | BK5: =BC5+BH5 -> 0 | BL5: =BK5-BJ5 -> 0 | BM5: =BJ5/$G5 -> 0 | BN5: =BK5/$G5 -> 0 | BO5: 0 | BP5: 0 | BQ5: =IFERROR(IF((BP5/BO5)>=1,100%,(BP5/BO5)),0%) -> 0 | BR5: =BJ5+BO5 -> 0 | BS5: =BK5+BP5 -> 0 | BT5: =BS5-BR5 -> 0 | BU5: =BR5/$G5 -> 0 | BV5: =BS5/$G5 -> 0 | BW5: 0 | BX5: 0 | BY5: =IFERROR(IF((BX5/BW5)>=1,100%,(BX5/BW5)),0%) -> 0 | BZ5: =BR5+BW5 -> 0 | CA5: =BS5+BX5 -> 0 | CB5: =CA5-BZ5 -> 0 | CC5: =BZ5/$G5 -> 0 | CD5: =CA5/$G5 -> 0 | CE5: 0 | CF5: 0 | CG5: =IFERROR(IF((CF5/CE5)>=1,100%,(CF5/CE5)),0%) -> 0 | CH5: =BZ5+CE5 -> 0 | CI5: =CA5+CF5 -> 0 | CJ5: =CI5-CH5 -> 0 | CK5: =CH5/$G5 -> 0 | CL5: =CI5/$G5 -> 0 | CM5: 0 | CN5: 0 | CO5: =IFERROR(IF((CN5/CM5)>=1,100%,(CN5/CM5)),0%) -> 0 | CP5: =CH5+CM5 -> 0 | CQ5: =CI5+CN5 -> 0 | CR5: =CQ5-CP5 -> 0 | CS5: =CP5/$G5 -> 0 | CT5: =CQ5/$G5 -> 0 | CU5: 0 | CV5: 0 | CW5: =IFERROR(IF((CV5/CU5)>=1,100%,(CV5/CU5)),0%) -> 0 | CX5: =CP5+CU5 -> 0 | CY5: =CQ5+CV5 -> 0 | CZ5: =CY5-CX5 -> 0 | DA5: =CX5/$G5 -> 0 | DB5: =CY5/$G5 -> 0 | DC5: 0 | DD5: 0 | DE5: 0 | DF5: =CX5+DC5 -> 0 | DG5: =CY5+DD5 -> 0 | DH5: =DG5-DF5 -> 0 | DI5: =DF5/$G5 -> 0 | DJ5: =DG5/$G5 -> 0 | DK5: 0 | DL5: 0 | DM5: =IFERROR(IF((DL5/DK5)>=1,100%,(DL5/DK5)),0%) -> 0 | DN5: =DF5+DK5 -> 0 | DO5: =DG5+DL5 -> 0 | DP5: =DO5-DN5 -> 0 | DQ5: =DN5/$G5 -> 0 | DR5: =DO5/$G5 -> 0
F6: 구현 | G6: 1 | H6: 1 | I6: =SUM(L6+T6+AB6+AJ6+AR6+AZ6+BH6+BP6+BX6+CF6+CN6+CV6+DD6+DL6+DT6+EB6+EJ6+ER6+EZ6+FI6+FR6+GB6+GL6+GV6+HF6+HP6+HZ6+IJ6+IT6+JD6+JN6+JX6+KH6+KR6+LB6+LL6+LV6+MF6+MP6+MZ6) -> 0 | J6: =IFERROR(IF((I6/H6)>=1,100%,(I6/H6)),0%) -> 0 | K6: 0 | L6: 0 | M6: =IFERROR(IF((L6/K6)>=1,100%,(L6/K6)),0%) -> 0 | N6: =+K6 -> 0 | O6: =+L6 -> 0 | P6: =O6-N6 -> 0 | Q6: =N6/$G6 -> 0 | R6: =O6/$G6 -> 0 | S6: 0 | T6: 0 | U6: =IFERROR(IF((T6/S6)>=1,100%,(T6/S6)),0%) -> 0 | V6: =N6+S6 -> 0 | W6: =O6+T6 -> 0 | X6: =W6-V6 -> 0 | Y6: =V6/$G6 -> 0 | Z6: =W6/$G6 -> 0 | AA6: 0 | AB6: 0 | AC6: =IFERROR(IF((AB6/AA6)>=1,100%,(AB6/AA6)),0%) -> 0 | AD6: =V6+AA6 -> 0 | AE6: =W6+AB6 -> 0 | AF6: =AE6-AD6 -> 0 | AG6: =AD6/$G6 -> 0 | AH6: =AE6/$G6 -> 0 | AI6: 0 | AJ6: 0 | AK6: =IFERROR(IF((AJ6/AI6)>=1,100%,(AJ6/AI6)),0%) -> 0 | AL6: =AD6+AI6 -> 0 | AM6: =AE6+AJ6 -> 0 | AN6: =AM6-AL6 -> 0 | AO6: =AL6/$G6 -> 0 | AP6: =AM6/$G6 -> 0 | AQ6: 0 | AR6: 0 | AS6: =IFERROR(IF((AR6/AQ6)>=1,100%,(AR6/AQ6)),0%) -> 0 | AT6: =AL6+AQ6 -> 0 | AU6: =AM6+AR6 -> 0 | AV6: =AU6-AT6 -> 0 | AW6: =AT6/$G6 -> 0 | AX6: =AU6/$G6 -> 0 | AY6: 0 | AZ6: 0 | BA6: =IFERROR(IF((AZ6/AY6)>=1,100%,(AZ6/AY6)),0%) -> 0 | BB6: =AT6+AY6 -> 0 | BC6: =AU6+AZ6 -> 0 | BD6: =BC6-BB6 -> 0 | BE6: =BB6/$G6 -> 0 | BF6: =BC6/$G6 -> 0 | BG6: 0 | BH6: 0 | BI6: =IFERROR(IF((BH6/BG6)>=1,100%,(BH6/BG6)),0%) -> 0 | BJ6: =BB6+BG6 -> 0 | BK6: =BC6+BH6 -> 0 | BL6: =BK6-BJ6 -> 0 | BM6: =BJ6/$G6 -> 0 | BN6: =BK6/$G6 -> 0 | BO6: 0 | BP6: 0 | BQ6: =IFERROR(IF((BP6/BO6)>=1,100%,(BP6/BO6)),0%) -> 0 | BR6: =BJ6+BO6 -> 0 | BS6: =BK6+BP6 -> 0 | BT6: =BS6-BR6 -> 0 | BU6: =BR6/$G6 -> 0 | BV6: =BS6/$G6 -> 0 | BW6: 0 | BX6: 0 | BY6: =IFERROR(IF((BX6/BW6)>=1,100%,(BX6/BW6)),0%) -> 0 | BZ6: =BR6+BW6 -> 0 | CA6: =BS6+BX6 -> 0 | CB6: =CA6-BZ6 -> 0 | CC6: =BZ6/$G6 -> 0 | CD6: =CA6/$G6 -> 0 | CE6: 0 | CF6: 0 | CG6: =IFERROR(IF((CF6/CE6)>=1,100%,(CF6/CE6)),0%) -> 0 | CH6: =BZ6+CE6 -> 0 | CI6: =CA6+CF6 -> 0 | CJ6: =CI6-CH6 -> 0 | CK6: =CH6/$G6 -> 0 | CL6: =CI6/$G6 -> 0 | CM6: 0 | CN6: 0 | CO6: =IFERROR(IF((CN6/CM6)>=1,100%,(CN6/CM6)),0%) -> 0 | CP6: =CH6+CM6 -> 0 | CQ6: =CI6+CN6 -> 0 | CR6: =CQ6-CP6 -> 0 | CS6: =CP6/$G6 -> 0 | CT6: =CQ6/$G6 -> 0 | CU6: 0 | CV6: 0 | CW6: =IFERROR(IF((CV6/CU6)>=1,100%,(CV6/CU6)),0%) -> 0 | CX6: =CP6+CU6 -> 0 | CY6: =CQ6+CV6 -> 0 | CZ6: =CY6-CX6 -> 0 | DA6: =CX6/$G6 -> 0 | DB6: =CY6/$G6 -> 0 | DC6: 0 | DD6: 0 | DE6: 0 | DF6: =CX6+DC6 -> 0 | DG6: =CY6+DD6 -> 0 | DH6: =DG6-DF6 -> 0 | DI6: =DF6/$G6 -> 0 | DJ6: =DG6/$G6 -> 0 | DK6: 0 | DL6: 0 | DM6: =IFERROR(IF((DL6/DK6)>=1,100%,(DL6/DK6)),0%) -> 0 | DN6: =DF6+DK6 -> 0 | DO6: =DG6+DL6 -> 0 | DP6: =DO6-DN6 -> 0 | DQ6: =DN6/$G6 -> 0 | DR6: =DO6/$G6 -> 0
F7: 테스트 | G7: 1 | H7: 1 | I7: =SUM(L7+T7+AB7+AJ7+AR7+AZ7+BH7+BP7+BX7+CF7+CN7+CV7+DD7+DL7+DT7+EB7+EJ7+ER7+EZ7+FI7+FR7+GB7+GL7+GV7+HF7+HP7+HZ7+IJ7+IT7+JD7+JN7+JX7+KH7+KR7+LB7+LL7+LV7+MF7+MP7+MZ7) -> 0 | J7: =IFERROR(IF((I7/H7)>=1,100%,(I7/H7)),0%) -> 0 | K7: 0 | L7: 0 | M7: =IFERROR(IF((L7/K7)>=1,100%,(L7/K7)),0%) -> 0 | N7: =+K7 -> 0 | O7: =+L7 -> 0 | P7: =O7-N7 -> 0 | Q7: =N7/$G7 -> 0 | R7: =O7/$G7 -> 0 | S7: 0 | T7: 0 | U7: =IFERROR(IF((T7/S7)>=1,100%,(T7/S7)),0%) -> 0 | V7: =N7+S7 -> 0 | W7: =O7+T7 -> 0 | X7: =W7-V7 -> 0 | Y7: =V7/$G7 -> 0 | Z7: =W7/$G7 -> 0 | AA7: 0 | AB7: 0 | AC7: =IFERROR(IF((AB7/AA7)>=1,100%,(AB7/AA7)),0%) -> 0 | AD7: =V7+AA7 -> 0 | AE7: =W7+AB7 -> 0 | AF7: =AE7-AD7 -> 0 | AG7: =AD7/$G7 -> 0 | AH7: =AE7/$G7 -> 0 | AI7: 0 | AJ7: 0 | AK7: =IFERROR(IF((AJ7/AI7)>=1,100%,(AJ7/AI7)),0%) -> 0 | AL7: =AD7+AI7 -> 0 | AM7: =AE7+AJ7 -> 0 | AN7: =AM7-AL7 -> 0 | AO7: =AL7/$G7 -> 0 | AP7: =AM7/$G7 -> 0 | AQ7: 0 | AR7: 0 | AS7: =IFERROR(IF((AR7/AQ7)>=1,100%,(AR7/AQ7)),0%) -> 0 | AT7: =AL7+AQ7 -> 0 | AU7: =AM7+AR7 -> 0 | AV7: =AU7-AT7 -> 0 | AW7: =AT7/$G7 -> 0 | AX7: =AU7/$G7 -> 0 | AY7: 0 | AZ7: 0 | BA7: =IFERROR(IF((AZ7/AY7)>=1,100%,(AZ7/AY7)),0%) -> 0 | BB7: =AT7+AY7 -> 0 | BC7: =AU7+AZ7 -> 0 | BD7: =BC7-BB7 -> 0 | BE7: =BB7/$G7 -> 0 | BF7: =BC7/$G7 -> 0 | BG7: 0 | BH7: 0 | BI7: =IFERROR(IF((BH7/BG7)>=1,100%,(BH7/BG7)),0%) -> 0 | BJ7: =BB7+BG7 -> 0 | BK7: =BC7+BH7 -> 0 | BL7: =BK7-BJ7 -> 0 | BM7: =BJ7/$G7 -> 0 | BN7: =BK7/$G7 -> 0 | BO7: 0 | BP7: 0 | BQ7: =IFERROR(IF((BP7/BO7)>=1,100%,(BP7/BO7)),0%) -> 0 | BR7: =BJ7+BO7 -> 0 | BS7: =BK7+BP7 -> 0 | BT7: =BS7-BR7 -> 0 | BU7: =BR7/$G7 -> 0 | BV7: =BS7/$G7 -> 0 | BW7: 0 | BX7: 0 | BY7: =IFERROR(IF((BX7/BW7)>=1,100%,(BX7/BW7)),0%) -> 0 | BZ7: =BR7+BW7 -> 0 | CA7: =BS7+BX7 -> 0 | CB7: =CA7-BZ7 -> 0 | CC7: =BZ7/$G7 -> 0 | CD7: =CA7/$G7 -> 0 | CE7: 0 | CF7: 0 | CG7: =IFERROR(IF((CF7/CE7)>=1,100%,(CF7/CE7)),0%) -> 0 | CH7: =BZ7+CE7 -> 0 | CI7: =CA7+CF7 -> 0 | CJ7: =CI7-CH7 -> 0 | CK7: =CH7/$G7 -> 0 | CL7: =CI7/$G7 -> 0 | CM7: 0 | CN7: 0 | CO7: =IFERROR(IF((CN7/CM7)>=1,100%,(CN7/CM7)),0%) -> 0 | CP7: =CH7+CM7 -> 0 | CQ7: =CI7+CN7 -> 0 | CR7: =CQ7-CP7 -> 0 | CS7: =CP7/$G7 -> 0 | CT7: =CQ7/$G7 -> 0 | CU7: 0 | CV7: 0 | CW7: =IFERROR(IF((CV7/CU7)>=1,100%,(CV7/CU7)),0%) -> 0 | CX7: =CP7+CU7 -> 0 | CY7: =CQ7+CV7 -> 0 | CZ7: =CY7-CX7 -> 0 | DA7: =CX7/$G7 -> 0 | DB7: =CY7/$G7 -> 0 | DC7: 0 | DD7: 0 | DE7: 0 | DF7: =CX7+DC7 -> 0 | DG7: =CY7+DD7 -> 0 | DH7: =DG7-DF7 -> 0 | DI7: =DF7/$G7 -> 0 | DJ7: =DG7/$G7 -> 0 | DK7: 0 | DL7: 0 | DM7: =IFERROR(IF((DL7/DK7)>=1,100%,(DL7/DK7)),0%) -> 0 | DN7: =DF7+DK7 -> 0 | DO7: =DG7+DL7 -> 0 | DP7: =DO7-DN7 -> 0 | DQ7: =DN7/$G7 -> 0 | DR7: =DO7/$G7 -> 0
C8: 건축물 모델링 | D8: 지적도 기반 건축물 모델링 | F8: 설계 | G8: 1 | H8: 1 | I8: =SUM(L8+T8+AB8+AJ8+AR8+AZ8+BH8+BP8+BX8+CF8+CN8+CV8+DD8+DL8+DT8+EB8+EJ8+ER8+EZ8+FI8+FR8+GB8+GL8+GV8+HF8+HP8+HZ8+IJ8+IT8+JD8+JN8+JX8+KH8+KR8+LB8+LL8+LV8+MF8+MP8+MZ8) -> 0 | J8: =IFERROR(IF((I8/H8)>=1,100%,(I8/H8)),0%) -> 0 | K8: 0 | L8: 0 | M8: =IFERROR(IF((L8/K8)>=1,100%,(L8/K8)),0%) -> 0 | N8: =+K8 -> 0 | O8: =+L8 -> 0 | P8: =O8-N8 -> 0 | Q8: =N8/$G8 -> 0 | R8: =O8/$G8 -> 0 | S8: 0 | T8: 0 | U8: =IFERROR(IF((T8/S8)>=1,100%,(T8/S8)),0%) -> 0 | V8: =N8+S8 -> 0 | W8: =O8+T8 -> 0 | X8: =W8-V8 -> 0 | Y8: =V8/$G8 -> 0 | Z8: =W8/$G8 -> 0 | AA8: 0 | AB8: 0 | AC8: =IFERROR(IF((AB8/AA8)>=1,100%,(AB8/AA8)),0%) -> 0 | AD8: =V8+AA8 -> 0 | AE8: =W8+AB8 -> 0 | AF8: =AE8-AD8 -> 0 | AG8: =AD8/$G8 -> 0 | AH8: =AE8/$G8 -> 0 | AI8: 0 | AJ8: 0 | AK8: =IFERROR(IF((AJ8/AI8)>=1,100%,(AJ8/AI8)),0%) -> 0 | AL8: =AD8+AI8 -> 0 | AM8: =AE8+AJ8 -> 0 | AN8: =AM8-AL8 -> 0 | AO8: =AL8/$G8 -> 0 | AP8: =AM8/$G8 -> 0 | AQ8: 0 | AR8: 0 | AS8: =IFERROR(IF((AR8/AQ8)>=1,100%,(AR8/AQ8)),0%) -> 0 | AT8: =AL8+AQ8 -> 0 | AU8: =AM8+AR8 -> 0 | AV8: =AU8-AT8 -> 0 | AW8: =AT8/$G8 -> 0 | AX8: =AU8/$G8 -> 0 | AY8: 0 | AZ8: 0 | BA8: =IFERROR(IF((AZ8/AY8)>=1,100%,(AZ8/AY8)),0%) -> 0 | BB8: =AT8+AY8 -> 0 | BC8: =AU8+AZ8 -> 0 | BD8: =BC8-BB8 -> 0 | BE8: =BB8/$G8 -> 0 | BF8: =BC8/$G8 -> 0 | BG8: 0 | BH8: 0 | BI8: =IFERROR(IF((BH8/BG8)>=1,100%,(BH8/BG8)),0%) -> 0 | BJ8: =BB8+BG8 -> 0 | BK8: =BC8+BH8 -> 0 | BL8: =BK8-BJ8 -> 0 | BM8: =BJ8/$G8 -> 0 | BN8: =BK8/$G8 -> 0 | BO8: 0 | BP8: 0 | BQ8: =IFERROR(IF((BP8/BO8)>=1,100%,(BP8/BO8)),0%) -> 0 | BR8: =BJ8+BO8 -> 0 | BS8: =BK8+BP8 -> 0 | BT8: =BS8-BR8 -> 0 | BU8: =BR8/$G8 -> 0 | BV8: =BS8/$G8 -> 0 | BW8: 0 | BX8: 0 | BY8: =IFERROR(IF((BX8/BW8)>=1,100%,(BX8/BW8)),0%) -> 0 | BZ8: =BR8+BW8 -> 0 | CA8: =BS8+BX8 -> 0 | CB8: =CA8-BZ8 -> 0 | CC8: =BZ8/$G8 -> 0 | CD8: =CA8/$G8 -> 0 | CE8: 0 | CF8: 0 | CG8: =IFERROR(IF((CF8/CE8)>=1,100%,(CF8/CE8)),0%) -> 0 | CH8: =BZ8+CE8 -> 0 | CI8: =CA8+CF8 -> 0 | CJ8: =CI8-CH8 -> 0 | CK8: =CH8/$G8 -> 0 | CL8: =CI8/$G8 -> 0 | CM8: 0 | CN8: 0 | CO8: =IFERROR(IF((CN8/CM8)>=1,100%,(CN8/CM8)),0%) -> 0 | CP8: =CH8+CM8 -> 0 | CQ8: =CI8+CN8 -> 0 | CR8: =CQ8-CP8 -> 0 | CS8: =CP8/$G8 -> 0 | CT8: =CQ8/$G8 -> 0 | CU8: 0 | CV8: 0 | CW8: =IFERROR(IF((CV8/CU8)>=1,100%,(CV8/CU8)),0%) -> 0 | CX8: =CP8+CU8 -> 0 | CY8: =CQ8+CV8 -> 0 | CZ8: =CY8-CX8 -> 0 | DA8: =CX8/$G8 -> 0 | DB8: =CY8/$G8 -> 0 | DC8: 0 | DD8: 0 | DE8: 0 | DF8: =CX8+DC8 -> 0 | DG8: =CY8+DD8 -> 0 | DH8: =DG8-DF8 -> 0 | DI8: =DF8/$G8 -> 0 | DJ8: =DG8/$G8 -> 0 | DK8: 0 | DL8: 0 | DM8: =IFERROR(IF((DL8/DK8)>=1,100%,(DL8/DK8)),0%) -> 0 | DN8: =DF8+DK8 -> 0 | DO8: =DG8+DL8 -> 0 | DP8: =DO8-DN8 -> 0 | DQ8: =DN8/$G8 -> 0 | DR8: =DO8/$G8 -> 0
F9: 구현 | G9: 1 | H9: 1 | I9: =SUM(L9+T9+AB9+AJ9+AR9+AZ9+BH9+BP9+BX9+CF9+CN9+CV9+DD9+DL9+DT9+EB9+EJ9+ER9+EZ9+FI9+FR9+GB9+GL9+GV9+HF9+HP9+HZ9+IJ9+IT9+JD9+JN9+JX9+KH9+KR9+LB9+LL9+LV9+MF9+MP9+MZ9) -> 0 | J9: =IFERROR(IF((I9/H9)>=1,100%,(I9/H9)),0%) -> 0 | K9: 0 | L9: 0 | M9: =IFERROR(IF((L9/K9)>=1,100%,(L9/K9)),0%) -> 0 | N9: =+K9 -> 0 | O9: =+L9 -> 0 | P9: =O9-N9 -> 0 | Q9: =N9/$G9 -> 0 | R9: =O9/$G9 -> 0 | S9: 0 | T9: 0 | U9: =IFERROR(IF((T9/S9)>=1,100%,(T9/S9)),0%) -> 0 | V9: =N9+S9 -> 0 | W9: =O9+T9 -> 0 | X9: =W9-V9 -> 0 | Y9: =V9/$G9 -> 0 | Z9: =W9/$G9 -> 0 | AA9: 0 | AB9: 0 | AC9: =IFERROR(IF((AB9/AA9)>=1,100%,(AB9/AA9)),0%) -> 0 | AD9: =V9+AA9 -> 0 | AE9: =W9+AB9 -> 0 | AF9: =AE9-AD9 -> 0 | AG9: =AD9/$G9 -> 0 | AH9: =AE9/$G9 -> 0 | AI9: 0 | AJ9: 0 | AK9: =IFERROR(IF((AJ9/AI9)>=1,100%,(AJ9/AI9)),0%) -> 0 | AL9: =AD9+AI9 -> 0 | AM9: =AE9+AJ9 -> 0 | AN9: =AM9-AL9 -> 0 | AO9: =AL9/$G9 -> 0 | AP9: =AM9/$G9 -> 0 | AQ9: 0 | AR9: 0 | AS9: =IFERROR(IF((AR9/AQ9)>=1,100%,(AR9/AQ9)),0%) -> 0 | AT9: =AL9+AQ9 -> 0 | AU9: =AM9+AR9 -> 0 | AV9: =AU9-AT9 -> 0 | AW9: =AT9/$G9 -> 0 | AX9: =AU9/$G9 -> 0 | AY9: 0 | AZ9: 0 | BA9: =IFERROR(IF((AZ9/AY9)>=1,100%,(AZ9/AY9)),0%) -> 0 | BB9: =AT9+AY9 -> 0 | BC9: =AU9+AZ9 -> 0 | BD9: =BC9-BB9 -> 0 | BE9: =BB9/$G9 -> 0 | BF9: =BC9/$G9 -> 0 | BG9: 0 | BH9: 0 | BI9: =IFERROR(IF((BH9/BG9)>=1,100%,(BH9/BG9)),0%) -> 0 | BJ9: =BB9+BG9 -> 0 | BK9: =BC9+BH9 -> 0 | BL9: =BK9-BJ9 -> 0 | BM9: =BJ9/$G9 -> 0 | BN9: =BK9/$G9 -> 0 | BO9: 0 | BP9: 0 | BQ9: =IFERROR(IF((BP9/BO9)>=1,100%,(BP9/BO9)),0%) -> 0 | BR9: =BJ9+BO9 -> 0 | BS9: =BK9+BP9 -> 0 | BT9: =BS9-BR9 -> 0 | BU9: =BR9/$G9 -> 0 | BV9: =BS9/$G9 -> 0 | BW9: 0 | BX9: 0 | BY9: =IFERROR(IF((BX9/BW9)>=1,100%,(BX9/BW9)),0%) -> 0 | BZ9: =BR9+BW9 -> 0 | CA9: =BS9+BX9 -> 0 | CB9: =CA9-BZ9 -> 0 | CC9: =BZ9/$G9 -> 0 | CD9: =CA9/$G9 -> 0 | CE9: 0 | CF9: 0 | CG9: =IFERROR(IF((CF9/CE9)>=1,100%,(CF9/CE9)),0%) -> 0 | CH9: =BZ9+CE9 -> 0 | CI9: =CA9+CF9 -> 0 | CJ9: =CI9-CH9 -> 0 | CK9: =CH9/$G9 -> 0 | CL9: =CI9/$G9 -> 0 | CM9: 0 | CN9: 0 | CO9: =IFERROR(IF((CN9/CM9)>=1,100%,(CN9/CM9)),0%) -> 0 | CP9: =CH9+CM9 -> 0 | CQ9: =CI9+CN9 -> 0 | CR9: =CQ9-CP9 -> 0 | CS9: =CP9/$G9 -> 0 | CT9: =CQ9/$G9 -> 0 | CU9: 0 | CV9: 0 | CW9: =IFERROR(IF((CV9/CU9)>=1,100%,(CV9/CU9)),0%) -> 0 | CX9: =CP9+CU9 -> 0 | CY9: =CQ9+CV9 -> 0 | CZ9: =CY9-CX9 -> 0 | DA9: =CX9/$G9 -> 0 | DB9: =CY9/$G9 -> 0 | DC9: 0 | DD9: 0 | DE9: 0 | DF9: =CX9+DC9 -> 0 | DG9: =CY9+DD9 -> 0 | DH9: =DG9-DF9 -> 0 | DI9: =DF9/$G9 -> 0 | DJ9: =DG9/$G9 -> 0 | DK9: 0 | DL9: 0 | DM9: =IFERROR(IF((DL9/DK9)>=1,100%,(DL9/DK9)),0%) -> 0 | DN9: =DF9+DK9 -> 0 | DO9: =DG9+DL9 -> 0 | DP9: =DO9-DN9 -> 0 | DQ9: =DN9/$G9 -> 0 | DR9: =DO9/$G9 -> 0
F10: 테스트 | G10: 1 | H10: 1 | I10: =SUM(L10+T10+AB10+AJ10+AR10+AZ10+BH10+BP10+BX10+CF10+CN10+CV10+DD10+DL10+DT10+EB10+EJ10+ER10+EZ10+FI10+FR10+GB10+GL10+GV10+HF10+HP10+HZ10+IJ10+IT10+JD10+JN10+JX10+KH10+KR10+LB10+LL10+LV10+MF10+MP10+MZ10) -> 0 | J10: =IFERROR(IF((I10/H10)>=1,100%,(I10/H10)),0%) -> 0 | K10: 0 | L10: 0 | M10: =IFERROR(IF((L10/K10)>=1,100%,(L10/K10)),0%) -> 0 | N10: =+K10 -> 0 | O10: =+L10 -> 0 | P10: =O10-N10 -> 0 | Q10: =N10/$G10 -> 0 | R10: =O10/$G10 -> 0 | S10: 0 | T10: 0 | U10: =IFERROR(IF((T10/S10)>=1,100%,(T10/S10)),0%) -> 0 | V10: =N10+S10 -> 0 | W10: =O10+T10 -> 0 | X10: =W10-V10 -> 0 | Y10: =V10/$G10 -> 0 | Z10: =W10/$G10 -> 0 | AA10: 0 | AB10: 0 | AC10: =IFERROR(IF((AB10/AA10)>=1,100%,(AB10/AA10)),0%) -> 0 | AD10: =V10+AA10 -> 0 | AE10: =W10+AB10 -> 0 | AF10: =AE10-AD10 -> 0 | AG10: =AD10/$G10 -> 0 | AH10: =AE10/$G10 -> 0 | AI10: 0 | AJ10: 0 | AK10: =IFERROR(IF((AJ10/AI10)>=1,100%,(AJ10/AI10)),0%) -> 0 | AL10: =AD10+AI10 -> 0 | AM10: =AE10+AJ10 -> 0 | AN10: =AM10-AL10 -> 0 | AO10: =AL10/$G10 -> 0 | AP10: =AM10/$G10 -> 0 | AQ10: 0 | AR10: 0 | AS10: =IFERROR(IF((AR10/AQ10)>=1,100%,(AR10/AQ10)),0%) -> 0 | AT10: =AL10+AQ10 -> 0 | AU10: =AM10+AR10 -> 0 | AV10: =AU10-AT10 -> 0 | AW10: =AT10/$G10 -> 0 | AX10: =AU10/$G10 -> 0 | AY10: 0 | AZ10: 0 | BA10: =IFERROR(IF((AZ10/AY10)>=1,100%,(AZ10/AY10)),0%) -> 0 | BB10: =AT10+AY10 -> 0 | BC10: =AU10+AZ10 -> 0 | BD10: =BC10-BB10 -> 0 | BE10: =BB10/$G10 -> 0 | BF10: =BC10/$G10 -> 0 | BG10: 0 | BH10: 0 | BI10: =IFERROR(IF((BH10/BG10)>=1,100%,(BH10/BG10)),0%) -> 0 | BJ10: =BB10+BG10 -> 0 | BK10: =BC10+BH10 -> 0 | BL10: =BK10-BJ10 -> 0 | BM10: =BJ10/$G10 -> 0 | BN10: =BK10/$G10 -> 0 | BO10: 0 | BP10: 0 | BQ10: =IFERROR(IF((BP10/BO10)>=1,100%,(BP10/BO10)),0%) -> 0 | BR10: =BJ10+BO10 -> 0 | BS10: =BK10+BP10 -> 0 | BT10: =BS10-BR10 -> 0 | BU10: =BR10/$G10 -> 0 | BV10: =BS10/$G10 -> 0 | BW10: 0 | BX10: 0 | BY10: =IFERROR(IF((BX10/BW10)>=1,100%,(BX10/BW10)),0%) -> 0 | BZ10: =BR10+BW10 -> 0 | CA10: =BS10+BX10 -> 0 | CB10: =CA10-BZ10 -> 0 | CC10: =BZ10/$G10 -> 0 | CD10: =CA10/$G10 -> 0 | CE10: 0 | CF10: 0 | CG10: =IFERROR(IF((CF10/CE10)>=1,100%,(CF10/CE10)),0%) -> 0 | CH10: =BZ10+CE10 -> 0 | CI10: =CA10+CF10 -> 0 | CJ10: =CI10-CH10 -> 0 | CK10: =CH10/$G10 -> 0 | CL10: =CI10/$G10 -> 0 | CM10: 0 | CN10: 0 | CO10: =IFERROR(IF((CN10/CM10)>=1,100%,(CN10/CM10)),0%) -> 0 | CP10: =CH10+CM10 -> 0 | CQ10: =CI10+CN10 -> 0 | CR10: =CQ10-CP10 -> 0 | CS10: =CP10/$G10 -> 0 | CT10: =CQ10/$G10 -> 0 | CU10: 0 | CV10: 0 | CW10: =IFERROR(IF((CV10/CU10)>=1,100%,(CV10/CU10)),0%) -> 0 | CX10: =CP10+CU10 -> 0 | CY10: =CQ10+CV10 -> 0 | CZ10: =CY10-CX10 -> 0 | DA10: =CX10/$G10 -> 0 | DB10: =CY10/$G10 -> 0 | DC10: 0 | DD10: 0 | DE10: 0 | DF10: =CX10+DC10 -> 0 | DG10: =CY10+DD10 -> 0 | DH10: =DG10-DF10 -> 0 | DI10: =DF10/$G10 -> 0 | DJ10: =DG10/$G10 -> 0 | DK10: 0 | DL10: 0 | DM10: =IFERROR(IF((DL10/DK10)>=1,100%,(DL10/DK10)),0%) -> 0 | DN10: =DF10+DK10 -> 0 | DO10: =DG10+DL10 -> 0 | DP10: =DO10-DN10 -> 0 | DQ10: =DN10/$G10 -> 0 | DR10: =DO10/$G10 -> 0
C11: 커스터마이징 모델링 | D11: 사용자 커스터마이징 모델링 | F11: 설계 | G11: 1 | H11: 1 | I11: =SUM(L11+T11+AB11+AJ11+AR11+AZ11+BH11+BP11+BX11+CF11+CN11+CV11+DD11+DL11+DT11+EB11+EJ11+ER11+EZ11+FI11+FR11+GB11+GL11+GV11+HF11+HP11+HZ11+IJ11+IT11+JD11+JN11+JX11+KH11+KR11+LB11+LL11+LV11+MF11+MP11+MZ11) -> 0 | J11: =IFERROR(IF((I11/H11)>=1,100%,(I11/H11)),0%) -> 0 | K11: 0 | L11: 0 | M11: =IFERROR(IF((L11/K11)>=1,100%,(L11/K11)),0%) -> 0 | N11: =+K11 -> 0 | O11: =+L11 -> 0 | P11: =O11-N11 -> 0 | Q11: =N11/$G11 -> 0 | R11: =O11/$G11 -> 0 | S11: 0 | T11: 0 | U11: =IFERROR(IF((T11/S11)>=1,100%,(T11/S11)),0%) -> 0 | V11: =N11+S11 -> 0 | W11: =O11+T11 -> 0 | X11: =W11-V11 -> 0 | Y11: =V11/$G11 -> 0 | Z11: =W11/$G11 -> 0 | AA11: 0 | AB11: 0 | AC11: =IFERROR(IF((AB11/AA11)>=1,100%,(AB11/AA11)),0%) -> 0 | AD11: =V11+AA11 -> 0 | AE11: =W11+AB11 -> 0 | AF11: =AE11-AD11 -> 0 | AG11: =AD11/$G11 -> 0 | AH11: =AE11/$G11 -> 0 | AI11: 0 | AJ11: 0 | AK11: =IFERROR(IF((AJ11/AI11)>=1,100%,(AJ11/AI11)),0%) -> 0 | AL11: =AD11+AI11 -> 0 | AM11: =AE11+AJ11 -> 0 | AN11: =AM11-AL11 -> 0 | AO11: =AL11/$G11 -> 0 | AP11: =AM11/$G11 -> 0 | AQ11: 0 | AR11: 0 | AS11: =IFERROR(IF((AR11/AQ11)>=1,100%,(AR11/AQ11)),0%) -> 0 | AT11: =AL11+AQ11 -> 0 | AU11: =AM11+AR11 -> 0 | AV11: =AU11-AT11 -> 0 | AW11: =AT11/$G11 -> 0 | AX11: =AU11/$G11 -> 0 | AY11: 0 | AZ11: 0 | BA11: =IFERROR(IF((AZ11/AY11)>=1,100%,(AZ11/AY11)),0%) -> 0 | BB11: =AT11+AY11 -> 0 | BC11: =AU11+AZ11 -> 0 | BD11: =BC11-BB11 -> 0 | BE11: =BB11/$G11 -> 0 | BF11: =BC11/$G11 -> 0 | BG11: 0 | BH11: 0 | BI11: =IFERROR(IF((BH11/BG11)>=1,100%,(BH11/BG11)),0%) -> 0 | BJ11: =BB11+BG11 -> 0 | BK11: =BC11+BH11 -> 0 | BL11: =BK11-BJ11 -> 0 | BM11: =BJ11/$G11 -> 0 | BN11: =BK11/$G11 -> 0 | BO11: 0 | BP11: 0 | BQ11: =IFERROR(IF((BP11/BO11)>=1,100%,(BP11/BO11)),0%) -> 0 | BR11: =BJ11+BO11 -> 0 | BS11: =BK11+BP11 -> 0 | BT11: =BS11-BR11 -> 0 | BU11: =BR11/$G11 -> 0 | BV11: =BS11/$G11 -> 0 | BW11: 0 | BX11: 0 | BY11: =IFERROR(IF((BX11/BW11)>=1,100%,(BX11/BW11)),0%) -> 0 | BZ11: =BR11+BW11 -> 0 | CA11: =BS11+BX11 -> 0 | CB11: =CA11-BZ11 -> 0 | CC11: =BZ11/$G11 -> 0 | CD11: =CA11/$G11 -> 0 | CE11: 0 | CF11: 0 | CG11: =IFERROR(IF((CF11/CE11)>=1,100%,(CF11/CE11)),0%) -> 0 | CH11: =BZ11+CE11 -> 0 | CI11: =CA11+CF11 -> 0 | CJ11: =CI11-CH11 -> 0 | CK11: =CH11/$G11 -> 0 | CL11: =CI11/$G11 -> 0 | CM11: 0 | CN11: 0 | CO11: =IFERROR(IF((CN11/CM11)>=1,100%,(CN11/CM11)),0%) -> 0 | CP11: =CH11+CM11 -> 0 | CQ11: =CI11+CN11 -> 0 | CR11: =CQ11-CP11 -> 0 | CS11: =CP11/$G11 -> 0 | CT11: =CQ11/$G11 -> 0 | CU11: 0 | CV11: 0 | CW11: =IFERROR(IF((CV11/CU11)>=1,100%,(CV11/CU11)),0%) -> 0 | CX11: =CP11+CU11 -> 0 | CY11: =CQ11+CV11 -> 0 | CZ11: =CY11-CX11 -> 0 | DA11: =CX11/$G11 -> 0 | DB11: =CY11/$G11 -> 0 | DC11: 0 | DD11: 0 | DE11: 0 | DF11: =CX11+DC11 -> 0 | DG11: =CY11+DD11 -> 0 | DH11: =DG11-DF11 -> 0 | DI11: =DF11/$G11 -> 0 | DJ11: =DG11/$G11 -> 0 | DK11: 0 | DL11: 0 | DM11: =IFERROR(IF((DL11/DK11)>=1,100%,(DL11/DK11)),0%) -> 0 | DN11: =DF11+DK11 -> 0 | DO11: =DG11+DL11 -> 0 | DP11: =DO11-DN11 -> 0 | DQ11: =DN11/$G11 -> 0 | DR11: =DO11/$G11 -> 0
F12: 구현 | G12: 1 | H12: 1 | I12: =SUM(L12+T12+AB12+AJ12+AR12+AZ12+BH12+BP12+BX12+CF12+CN12+CV12+DD12+DL12+DT12+EB12+EJ12+ER12+EZ12+FI12+FR12+GB12+GL12+GV12+HF12+HP12+HZ12+IJ12+IT12+JD12+JN12+JX12+KH12+KR12+LB12+LL12+LV12+MF12+MP12+MZ12) -> 0 | J12: =IFERROR(IF((I12/H12)>=1,100%,(I12/H12)),0%) -> 0 | K12: 0 | L12: 0 | M12: =IFERROR(IF((L12/K12)>=1,100%,(L12/K12)),0%) -> 0 | N12: =+K12 -> 0 | O12: =+L12 -> 0 | P12: =O12-N12 -> 0 | Q12: =N12/$G12 -> 0 | R12: =O12/$G12 -> 0 | S12: 0 | T12: 0 | U12: =IFERROR(IF((T12/S12)>=1,100%,(T12/S12)),0%) -> 0 | V12: =N12+S12 -> 0 | W12: =O12+T12 -> 0 | X12: =W12-V12 -> 0 | Y12: =V12/$G12 -> 0 | Z12: =W12/$G12 -> 0 | AA12: 0 | AB12: 0 | AC12: =IFERROR(IF((AB12/AA12)>=1,100%,(AB12/AA12)),0%) -> 0 | AD12: =V12+AA12 -> 0 | AE12: =W12+AB12 -> 0 | AF12: =AE12-AD12 -> 0 | AG12: =AD12/$G12 -> 0 | AH12: =AE12/$G12 -> 0 | AI12: 0 | AJ12: 0 | AK12: =IFERROR(IF((AJ12/AI12)>=1,100%,(AJ12/AI12)),0%) -> 0 | AL12: =AD12+AI12 -> 0 | AM12: =AE12+AJ12 -> 0 | AN12: =AM12-AL12 -> 0 | AO12: =AL12/$G12 -> 0 | AP12: =AM12/$G12 -> 0 | AQ12: 0 | AR12: 0 | AS12: =IFERROR(IF((AR12/AQ12)>=1,100%,(AR12/AQ12)),0%) -> 0 | AT12: =AL12+AQ12 -> 0 | AU12: =AM12+AR12 -> 0 | AV12: =AU12-AT12 -> 0 | AW12: =AT12/$G12 -> 0 | AX12: =AU12/$G12 -> 0 | AY12: 0 | AZ12: 0 | BA12: =IFERROR(IF((AZ12/AY12)>=1,100%,(AZ12/AY12)),0%) -> 0 | BB12: =AT12+AY12 -> 0 | BC12: =AU12+AZ12 -> 0 | BD12: =BC12-BB12 -> 0 | BE12: =BB12/$G12 -> 0 | BF12: =BC12/$G12 -> 0 | BG12: 0 | BH12: 0 | BI12: =IFERROR(IF((BH12/BG12)>=1,100%,(BH12/BG12)),0%) -> 0 | BJ12: =BB12+BG12 -> 0 | BK12: =BC12+BH12 -> 0 | BL12: =BK12-BJ12 -> 0 | BM12: =BJ12/$G12 -> 0 | BN12: =BK12/$G12 -> 0 | BO12: 0 | BP12: 0 | BQ12: =IFERROR(IF((BP12/BO12)>=1,100%,(BP12/BO12)),0%) -> 0 | BR12: =BJ12+BO12 -> 0 | BS12: =BK12+BP12 -> 0 | BT12: =BS12-BR12 -> 0 | BU12: =BR12/$G12 -> 0 | BV12: =BS12/$G12 -> 0 | BW12: 0 | BX12: 0 | BY12: =IFERROR(IF((BX12/BW12)>=1,100%,(BX12/BW12)),0%) -> 0 | BZ12: =BR12+BW12 -> 0 | CA12: =BS12+BX12 -> 0 | CB12: =CA12-BZ12 -> 0 | CC12: =BZ12/$G12 -> 0 | CD12: =CA12/$G12 -> 0 | CE12: 0 | CF12: 0 | CG12: =IFERROR(IF((CF12/CE12)>=1,100%,(CF12/CE12)),0%) -> 0 | CH12: =BZ12+CE12 -> 0 | CI12: =CA12+CF12 -> 0 | CJ12: =CI12-CH12 -> 0 | CK12: =CH12/$G12 -> 0 | CL12: =CI12/$G12 -> 0 | CM12: 0 | CN12: 0 | CO12: =IFERROR(IF((CN12/CM12)>=1,100%,(CN12/CM12)),0%) -> 0 | CP12: =CH12+CM12 -> 0 | CQ12: =CI12+CN12 -> 0 | CR12: =CQ12-CP12 -> 0 | CS12: =CP12/$G12 -> 0 | CT12: =CQ12/$G12 -> 0 | CU12: 0 | CV12: 0 | CW12: =IFERROR(IF((CV12/CU12)>=1,100%,(CV12/CU12)),0%) -> 0 | CX12: =CP12+CU12 -> 0 | CY12: =CQ12+CV12 -> 0 | CZ12: =CY12-CX12 -> 0 | DA12: =CX12/$G12 -> 0 | DB12: =CY12/$G12 -> 0 | DC12: 0 | DD12: 0 | DE12: 0 | DF12: =CX12+DC12 -> 0 | DG12: =CY12+DD12 -> 0 | DH12: =DG12-DF12 -> 0 | DI12: =DF12/$G12 -> 0 | DJ12: =DG12/$G12 -> 0 | DK12: 0 | DL12: 0 | DM12: =IFERROR(IF((DL12/DK12)>=1,100%,(DL12/DK12)),0%) -> 0 | DN12: =DF12+DK12 -> 0 | DO12: =DG12+DL12 -> 0 | DP12: =DO12-DN12 -> 0 | DQ12: =DN12/$G12 -> 0 | DR12: =DO12/$G12 -> 0
F13: 테스트 | G13: 1 | H13: 1 | I13: =SUM(L13+T13+AB13+AJ13+AR13+AZ13+BH13+BP13+BX13+CF13+CN13+CV13+DD13+DL13+DT13+EB13+EJ13+ER13+EZ13+FI13+FR13+GB13+GL13+GV13+HF13+HP13+HZ13+IJ13+IT13+JD13+JN13+JX13+KH13+KR13+LB13+LL13+LV13+MF13+MP13+MZ13) -> 0 | J13: =IFERROR(IF((I13/H13)>=1,100%,(I13/H13)),0%) -> 0 | K13: 0 | L13: 0 | M13: =IFERROR(IF((L13/K13)>=1,100%,(L13/K13)),0%) -> 0 | N13: =+K13 -> 0 | O13: =+L13 -> 0 | P13: =O13-N13 -> 0 | Q13: =N13/$G13 -> 0 | R13: =O13/$G13 -> 0 | S13: 0 | T13: 0 | U13: =IFERROR(IF((T13/S13)>=1,100%,(T13/S13)),0%) -> 0 | V13: =N13+S13 -> 0 | W13: =O13+T13 -> 0 | X13: =W13-V13 -> 0 | Y13: =V13/$G13 -> 0 | Z13: =W13/$G13 -> 0 | AA13: 0 | AB13: 0 | AC13: =IFERROR(IF((AB13/AA13)>=1,100%,(AB13/AA13)),0%) -> 0 | AD13: =V13+AA13 -> 0 | AE13: =W13+AB13 -> 0 | AF13: =AE13-AD13 -> 0 | AG13: =AD13/$G13 -> 0 | AH13: =AE13/$G13 -> 0 | AI13: 0 | AJ13: 0 | AK13: =IFERROR(IF((AJ13/AI13)>=1,100%,(AJ13/AI13)),0%) -> 0 | AL13: =AD13+AI13 -> 0 | AM13: =AE13+AJ13 -> 0 | AN13: =AM13-AL13 -> 0 | AO13: =AL13/$G13 -> 0 | AP13: =AM13/$G13 -> 0 | AQ13: 0 | AR13: 0 | AS13: =IFERROR(IF((AR13/AQ13)>=1,100%,(AR13/AQ13)),0%) -> 0 | AT13: =AL13+AQ13 -> 0 | AU13: =AM13+AR13 -> 0 | AV13: =AU13-AT13 -> 0 | AW13: =AT13/$G13 -> 0 | AX13: =AU13/$G13 -> 0 | AY13: 0 | AZ13: 0 | BA13: =IFERROR(IF((AZ13/AY13)>=1,100%,(AZ13/AY13)),0%) -> 0 | BB13: =AT13+AY13 -> 0 | BC13: =AU13+AZ13 -> 0 | BD13: =BC13-BB13 -> 0 | BE13: =BB13/$G13 -> 0 | BF13: =BC13/$G13 -> 0 | BG13: 0 | BH13: 0 | BI13: =IFERROR(IF((BH13/BG13)>=1,100%,(BH13/BG13)),0%) -> 0 | BJ13: =BB13+BG13 -> 0 | BK13: =BC13+BH13 -> 0 | BL13: =BK13-BJ13 -> 0 | BM13: =BJ13/$G13 -> 0 | BN13: =BK13/$G13 -> 0 | BO13: 0 | BP13: 0 | BQ13: =IFERROR(IF((BP13/BO13)>=1,100%,(BP13/BO13)),0%) -> 0 | BR13: =BJ13+BO13 -> 0 | BS13: =BK13+BP13 -> 0 | BT13: =BS13-BR13 -> 0 | BU13: =BR13/$G13 -> 0 | BV13: =BS13/$G13 -> 0 | BW13: 0 | BX13: 0 | BY13: =IFERROR(IF((BX13/BW13)>=1,100%,(BX13/BW13)),0%) -> 0 | BZ13: =BR13+BW13 -> 0 | CA13: =BS13+BX13 -> 0 | CB13: =CA13-BZ13 -> 0 | CC13: =BZ13/$G13 -> 0 | CD13: =CA13/$G13 -> 0 | CE13: 0 | CF13: 0 | CG13: =IFERROR(IF((CF13/CE13)>=1,100%,(CF13/CE13)),0%) -> 0 | CH13: =BZ13+CE13 -> 0 | CI13: =CA13+CF13 -> 0 | CJ13: =CI13-CH13 -> 0 | CK13: =CH13/$G13 -> 0 | CL13: =CI13/$G13 -> 0 | CM13: 0 | CN13: 0 | CO13: =IFERROR(IF((CN13/CM13)>=1,100%,(CN13/CM13)),0%) -> 0 | CP13: =CH13+CM13 -> 0 | CQ13: =CI13+CN13 -> 0 | CR13: =CQ13-CP13 -> 0 | CS13: =CP13/$G13 -> 0 | CT13: =CQ13/$G13 -> 0 | CU13: 0 | CV13: 0 | CW13: =IFERROR(IF((CV13/CU13)>=1,100%,(CV13/CU13)),0%) -> 0 | CX13: =CP13+CU13 -> 0 | CY13: =CQ13+CV13 -> 0 | CZ13: =CY13-CX13 -> 0 | DA13: =CX13/$G13 -> 0 | DB13: =CY13/$G13 -> 0 | DC13: 0 | DD13: 0 | DE13: 0 | DF13: =CX13+DC13 -> 0 | DG13: =CY13+DD13 -> 0 | DH13: =DG13-DF13 -> 0 | DI13: =DF13/$G13 -> 0 | DJ13: =DG13/$G13 -> 0 | DK13: 0 | DL13: 0 | DM13: =IFERROR(IF((DL13/DK13)>=1,100%,(DL13/DK13)),0%) -> 0 | DN13: =DF13+DK13 -> 0 | DO13: =DG13+DL13 -> 0 | DP13: =DO13-DN13 -> 0 | DQ13: =DN13/$G13 -> 0 | DR13: =DO13/$G13 -> 0
B14: VR메타버스 | C14: 도시탐색 | D14: 건물위치 및 인터렉티브 기즈모 배치 | F14: 설계 | G14: 1 | H14: 1 | I14: =SUM(L14+T14+AB14+AJ14+AR14+AZ14+BH14+BP14+BX14+CF14+CN14+CV14+DD14+DL14+DT14+EB14+EJ14+ER14+EZ14+FI14+FR14+GB14+GL14+GV14+HF14+HP14+HZ14+IJ14+IT14+JD14+JN14+JX14+KH14+KR14+LB14+LL14+LV14+MF14+MP14+MZ14) -> 0 | J14: =IFERROR(IF((I14/H14)>=1,100%,(I14/H14)),0%) -> 0 | K14: 0 | L14: 0 | M14: =IFERROR(IF((L14/K14)>=1,100%,(L14/K14)),0%) -> 0 | N14: =+K14 -> 0 | O14: =+L14 -> 0 | P14: =O14-N14 -> 0 | Q14: =N14/$G14 -> 0 | R14: =O14/$G14 -> 0 | S14: 0 | T14: 0 | U14: =IFERROR(IF((T14/S14)>=1,100%,(T14/S14)),0%) -> 0 | V14: =N14+S14 -> 0 | W14: =O14+T14 -> 0 | X14: =W14-V14 -> 0 | Y14: =V14/$G14 -> 0 | Z14: =W14/$G14 -> 0 | AA14: 0 | AB14: 0 | AC14: =IFERROR(IF((AB14/AA14)>=1,100%,(AB14/AA14)),0%) -> 0 | AD14: =V14+AA14 -> 0 | AE14: =W14+AB14 -> 0 | AF14: =AE14-AD14 -> 0 | AG14: =AD14/$G14 -> 0 | AH14: =AE14/$G14 -> 0 | AI14: 0 | AJ14: 0 | AK14: =IFERROR(IF((AJ14/AI14)>=1,100%,(AJ14/AI14)),0%) -> 0 | AL14: =AD14+AI14 -> 0 | AM14: =AE14+AJ14 -> 0 | AN14: =AM14-AL14 -> 0 | AO14: =AL14/$G14 -> 0 | AP14: =AM14/$G14 -> 0 | AQ14: 0 | AR14: 0 | AS14: =IFERROR(IF((AR14/AQ14)>=1,100%,(AR14/AQ14)),0%) -> 0 | AT14: =AL14+AQ14 -> 0 | AU14: =AM14+AR14 -> 0 | AV14: =AU14-AT14 -> 0 | AW14: =AT14/$G14 -> 0 | AX14: =AU14/$G14 -> 0 | AY14: 0 | AZ14: 0 | BA14: =IFERROR(IF((AZ14/AY14)>=1,100%,(AZ14/AY14)),0%) -> 0 | BB14: =AT14+AY14 -> 0 | BC14: =AU14+AZ14 -> 0 | BD14: =BC14-BB14 -> 0 | BE14: =BB14/$G14 -> 0 | BF14: =BC14/$G14 -> 0 | BG14: 0 | BH14: 0 | BI14: =IFERROR(IF((BH14/BG14)>=1,100%,(BH14/BG14)),0%) -> 0 | BJ14: =BB14+BG14 -> 0 | BK14: =BC14+BH14 -> 0 | BL14: =BK14-BJ14 -> 0 | BM14: =BJ14/$G14 -> 0 | BN14: =BK14/$G14 -> 0 | BO14: 0 | BP14: 0 | BQ14: =IFERROR(IF((BP14/BO14)>=1,100%,(BP14/BO14)),0%) -> 0 | BR14: =BJ14+BO14 -> 0 | BS14: =BK14+BP14 -> 0 | BT14: =BS14-BR14 -> 0 | BU14: =BR14/$G14 -> 0 | BV14: =BS14/$G14 -> 0 | BW14: 0 | BX14: 0 | BY14: =IFERROR(IF((BX14/BW14)>=1,100%,(BX14/BW14)),0%) -> 0 | BZ14: =BR14+BW14 -> 0 | CA14: =BS14+BX14 -> 0 | CB14: =CA14-BZ14 -> 0 | CC14: =BZ14/$G14 -> 0 | CD14: =CA14/$G14 -> 0 | CE14: 0 | CF14: 0 | CG14: =IFERROR(IF((CF14/CE14)>=1,100%,(CF14/CE14)),0%) -> 0 | CH14: =BZ14+CE14 -> 0 | CI14: =CA14+CF14 -> 0 | CJ14: =CI14-CH14 -> 0 | CK14: =CH14/$G14 -> 0 | CL14: =CI14/$G14 -> 0 | CM14: 0 | CN14: 0 | CO14: =IFERROR(IF((CN14/CM14)>=1,100%,(CN14/CM14)),0%) -> 0 | CP14: =CH14+CM14 -> 0 | CQ14: =CI14+CN14 -> 0 | CR14: =CQ14-CP14 -> 0 | CS14: =CP14/$G14 -> 0 | CT14: =CQ14/$G14 -> 0 | CU14: 0 | CV14: 0 | CW14: =IFERROR(IF((CV14/CU14)>=1,100%,(CV14/CU14)),0%) -> 0 | CX14: =CP14+CU14 -> 0 | CY14: =CQ14+CV14 -> 0 | CZ14: =CY14-CX14 -> 0 | DA14: =CX14/$G14 -> 0 | DB14: =CY14/$G14 -> 0 | DC14: 0 | DD14: 0 | DE14: 0 | DF14: =CX14+DC14 -> 0 | DG14: =CY14+DD14 -> 0 | DH14: =DG14-DF14 -> 0 | DI14: =DF14/$G14 -> 0 | DJ14: =DG14/$G14 -> 0 | DK14: 0 | DL14: 0 | DM14: =IFERROR(IF((DL14/DK14)>=1,100%,(DL14/DK14)),0%) -> 0 | DN14: =DF14+DK14 -> 0 | DO14: =DG14+DL14 -> 0 | DP14: =DO14-DN14 -> 0 | DQ14: =DN14/$G14 -> 0 | DR14: =DO14/$G14 -> 0
F15: 구현 | G15: 1 | H15: 1 | I15: =SUM(L15+T15+AB15+AJ15+AR15+AZ15+BH15+BP15+BX15+CF15+CN15+CV15+DD15+DL15+DT15+EB15+EJ15+ER15+EZ15+FI15+FR15+GB15+GL15+GV15+HF15+HP15+HZ15+IJ15+IT15+JD15+JN15+JX15+KH15+KR15+LB15+LL15+LV15+MF15+MP15+MZ15) -> 0 | J15: =IFERROR(IF((I15/H15)>=1,100%,(I15/H15)),0%) -> 0 | K15: 0 | L15: 0 | M15: =IFERROR(IF((L15/K15)>=1,100%,(L15/K15)),0%) -> 0 | N15: =+K15 -> 0 | O15: =+L15 -> 0 | P15: =O15-N15 -> 0 | Q15: =N15/$G15 -> 0 | R15: =O15/$G15 -> 0 | S15: 0 | T15: 0 | U15: =IFERROR(IF((T15/S15)>=1,100%,(T15/S15)),0%) -> 0 | V15: =N15+S15 -> 0 | W15: =O15+T15 -> 0 | X15: =W15-V15 -> 0 | Y15: =V15/$G15 -> 0 | Z15: =W15/$G15 -> 0 | AA15: 0 | AB15: 0 | AC15: =IFERROR(IF((AB15/AA15)>=1,100%,(AB15/AA15)),0%) -> 0 | AD15: =V15+AA15 -> 0 | AE15: =W15+AB15 -> 0 | AF15: =AE15-AD15 -> 0 | AG15: =AD15/$G15 -> 0 | AH15: =AE15/$G15 -> 0 | AI15: 0 | AJ15: 0 | AK15: =IFERROR(IF((AJ15/AI15)>=1,100%,(AJ15/AI15)),0%) -> 0 | AL15: =AD15+AI15 -> 0 | AM15: =AE15+AJ15 -> 0 | AN15: =AM15-AL15 -> 0 | AO15: =AL15/$G15 -> 0 | AP15: =AM15/$G15 -> 0 | AQ15: 0 | AR15: 0 | AS15: =IFERROR(IF((AR15/AQ15)>=1,100%,(AR15/AQ15)),0%) -> 0 | AT15: =AL15+AQ15 -> 0 | AU15: =AM15+AR15 -> 0 | AV15: =AU15-AT15 -> 0 | AW15: =AT15/$G15 -> 0 | AX15: =AU15/$G15 -> 0 | AY15: 0 | AZ15: 0 | BA15: =IFERROR(IF((AZ15/AY15)>=1,100%,(AZ15/AY15)),0%) -> 0 | BB15: =AT15+AY15 -> 0 | BC15: =AU15+AZ15 -> 0 | BD15: =BC15-BB15 -> 0 | BE15: =BB15/$G15 -> 0 | BF15: =BC15/$G15 -> 0 | BG15: 0 | BH15: 0 | BI15: =IFERROR(IF((BH15/BG15)>=1,100%,(BH15/BG15)),0%) -> 0 | BJ15: =BB15+BG15 -> 0 | BK15: =BC15+BH15 -> 0 | BL15: =BK15-BJ15 -> 0 | BM15: =BJ15/$G15 -> 0 | BN15: =BK15/$G15 -> 0 | BO15: 0 | BP15: 0 | BQ15: =IFERROR(IF((BP15/BO15)>=1,100%,(BP15/BO15)),0%) -> 0 | BR15: =BJ15+BO15 -> 0 | BS15: =BK15+BP15 -> 0 | BT15: =BS15-BR15 -> 0 | BU15: =BR15/$G15 -> 0 | BV15: =BS15/$G15 -> 0 | BW15: 0 | BX15: 0 | BY15: =IFERROR(IF((BX15/BW15)>=1,100%,(BX15/BW15)),0%) -> 0 | BZ15: =BR15+BW15 -> 0 | CA15: =BS15+BX15 -> 0 | CB15: =CA15-BZ15 -> 0 | CC15: =BZ15/$G15 -> 0 | CD15: =CA15/$G15 -> 0 | CE15: 0 | CF15: 0 | CG15: =IFERROR(IF((CF15/CE15)>=1,100%,(CF15/CE15)),0%) -> 0 | CH15: =BZ15+CE15 -> 0 | CI15: =CA15+CF15 -> 0 | CJ15: =CI15-CH15 -> 0 | CK15: =CH15/$G15 -> 0 | CL15: =CI15/$G15 -> 0 | CM15: 0 | CN15: 0 | CO15: =IFERROR(IF((CN15/CM15)>=1,100%,(CN15/CM15)),0%) -> 0 | CP15: =CH15+CM15 -> 0 | CQ15: =CI15+CN15 -> 0 | CR15: =CQ15-CP15 -> 0 | CS15: =CP15/$G15 -> 0 | CT15: =CQ15/$G15 -> 0 | CU15: 0 | CV15: 0 | CW15: =IFERROR(IF((CV15/CU15)>=1,100%,(CV15/CU15)),0%) -> 0 | CX15: =CP15+CU15 -> 0 | CY15: =CQ15+CV15 -> 0 | CZ15: =CY15-CX15 -> 0 | DA15: =CX15/$G15 -> 0 | DB15: =CY15/$G15 -> 0 | DC15: 0 | DD15: 0 | DE15: 0 | DF15: =CX15+DC15 -> 0 | DG15: =CY15+DD15 -> 0 | DH15: =DG15-DF15 -> 0 | DI15: =DF15/$G15 -> 0 | DJ15: =DG15/$G15 -> 0 | DK15: 0 | DL15: 0 | DM15: =IFERROR(IF((DL15/DK15)>=1,100%,(DL15/DK15)),0%) -> 0 | DN15: =DF15+DK15 -> 0 | DO15: =DG15+DL15 -> 0 | DP15: =DO15-DN15 -> 0 | DQ15: =DN15/$G15 -> 0 | DR15: =DO15/$G15 -> 0
F16: 테스트 | G16: 1 | H16: 1 | I16: =SUM(L16+T16+AB16+AJ16+AR16+AZ16+BH16+BP16+BX16+CF16+CN16+CV16+DD16+DL16+DT16+EB16+EJ16+ER16+EZ16+FI16+FR16+GB16+GL16+GV16+HF16+HP16+HZ16+IJ16+IT16+JD16+JN16+JX16+KH16+KR16+LB16+LL16+LV16+MF16+MP16+MZ16) -> 0 | J16: =IFERROR(IF((I16/H16)>=1,100%,(I16/H16)),0%) -> 0 | K16: 0 | L16: 0 | M16: =IFERROR(IF((L16/K16)>=1,100%,(L16/K16)),0%) -> 0 | N16: =+K16 -> 0 | O16: =+L16 -> 0 | P16: =O16-N16 -> 0 | Q16: =N16/$G16 -> 0 | R16: =O16/$G16 -> 0 | S16: 0 | T16: 0 | U16: =IFERROR(IF((T16/S16)>=1,100%,(T16/S16)),0%) -> 0 | V16: =N16+S16 -> 0 | W16: =O16+T16 -> 0 | X16: =W16-V16 -> 0 | Y16: =V16/$G16 -> 0 | Z16: =W16/$G16 -> 0 | AA16: 0 | AB16: 0 | AC16: =IFERROR(IF((AB16/AA16)>=1,100%,(AB16/AA16)),0%) -> 0 | AD16: =V16+AA16 -> 0 | AE16: =W16+AB16 -> 0 | AF16: =AE16-AD16 -> 0 | AG16: =AD16/$G16 -> 0 | AH16: =AE16/$G16 -> 0 | AI16: 0 | AJ16: 0 | AK16: =IFERROR(IF((AJ16/AI16)>=1,100%,(AJ16/AI16)),0%) -> 0 | AL16: =AD16+AI16 -> 0 | AM16: =AE16+AJ16 -> 0 | AN16: =AM16-AL16 -> 0 | AO16: =AL16/$G16 -> 0 | AP16: =AM16/$G16 -> 0 | AQ16: 0 | AR16: 0 | AS16: =IFERROR(IF((AR16/AQ16)>=1,100%,(AR16/AQ16)),0%) -> 0 | AT16: =AL16+AQ16 -> 0 | AU16: =AM16+AR16 -> 0 | AV16: =AU16-AT16 -> 0 | AW16: =AT16/$G16 -> 0 | AX16: =AU16/$G16 -> 0 | AY16: 0 | AZ16: 0 | BA16: =IFERROR(IF((AZ16/AY16)>=1,100%,(AZ16/AY16)),0%) -> 0 | BB16: =AT16+AY16 -> 0 | BC16: =AU16+AZ16 -> 0 | BD16: =BC16-BB16 -> 0 | BE16: =BB16/$G16 -> 0 | BF16: =BC16/$G16 -> 0 | BG16: 0 | BH16: 0 | BI16: =IFERROR(IF((BH16/BG16)>=1,100%,(BH16/BG16)),0%) -> 0 | BJ16: =BB16+BG16 -> 0 | BK16: =BC16+BH16 -> 0 | BL16: =BK16-BJ16 -> 0 | BM16: =BJ16/$G16 -> 0 | BN16: =BK16/$G16 -> 0 | BO16: 0 | BP16: 0 | BQ16: =IFERROR(IF((BP16/BO16)>=1,100%,(BP16/BO16)),0%) -> 0 | BR16: =BJ16+BO16 -> 0 | BS16: =BK16+BP16 -> 0 | BT16: =BS16-BR16 -> 0 | BU16: =BR16/$G16 -> 0 | BV16: =BS16/$G16 -> 0 | BW16: 0 | BX16: 0 | BY16: =IFERROR(IF((BX16/BW16)>=1,100%,(BX16/BW16)),0%) -> 0 | BZ16: =BR16+BW16 -> 0 | CA16: =BS16+BX16 -> 0 | CB16: =CA16-BZ16 -> 0 | CC16: =BZ16/$G16 -> 0 | CD16: =CA16/$G16 -> 0 | CE16: 0 | CF16: 0 | CG16: =IFERROR(IF((CF16/CE16)>=1,100%,(CF16/CE16)),0%) -> 0 | CH16: =BZ16+CE16 -> 0 | CI16: =CA16+CF16 -> 0 | CJ16: =CI16-CH16 -> 0 | CK16: =CH16/$G16 -> 0 | CL16: =CI16/$G16 -> 0 | CM16: 0 | CN16: 0 | CO16: =IFERROR(IF((CN16/CM16)>=1,100%,(CN16/CM16)),0%) -> 0 | CP16: =CH16+CM16 -> 0 | CQ16: =CI16+CN16 -> 0 | CR16: =CQ16-CP16 -> 0 | CS16: =CP16/$G16 -> 0 | CT16: =CQ16/$G16 -> 0 | CU16: 0 | CV16: 0 | CW16: =IFERROR(IF((CV16/CU16)>=1,100%,(CV16/CU16)),0%) -> 0 | CX16: =CP16+CU16 -> 0 | CY16: =CQ16+CV16 -> 0 | CZ16: =CY16-CX16 -> 0 | DA16: =CX16/$G16 -> 0 | DB16: =CY16/$G16 -> 0 | DC16: 0 | DD16: 0 | DE16: 0 | DF16: =CX16+DC16 -> 0 | DG16: =CY16+DD16 -> 0 | DH16: =DG16-DF16 -> 0 | DI16: =DF16/$G16 -> 0 | DJ16: =DG16/$G16 -> 0 | DK16: 0 | DL16: 0 | DM16: =IFERROR(IF((DL16/DK16)>=1,100%,(DL16/DK16)),0%) -> 0 | DN16: =DF16+DK16 -> 0 | DO16: =DG16+DL16 -> 0 | DP16: =DO16-DN16 -> 0 | DQ16: =DN16/$G16 -> 0 | DR16: =DO16/$G16 -> 0
C17: 아바타속도조절 | D17: 아바타 속도조절 | F17: 설계 | G17: 1 | H17: 1 | I17: =SUM(L17+T17+AB17+AJ17+AR17+AZ17+BH17+BP17+BX17+CF17+CN17+CV17+DD17+DL17+DT17+EB17+EJ17+ER17+EZ17+FI17+FR17+GB17+GL17+GV17+HF17+HP17+HZ17+IJ17+IT17+JD17+JN17+JX17+KH17+KR17+LB17+LL17+LV17+MF17+MP17+MZ17) -> 0 | J17: =IFERROR(IF((I17/H17)>=1,100%,(I17/H17)),0%) -> 0 | K17: 0 | L17: 0 | M17: =IFERROR(IF((L17/K17)>=1,100%,(L17/K17)),0%) -> 0 | N17: =+K17 -> 0 | O17: =+L17 -> 0 | P17: =O17-N17 -> 0 | Q17: =N17/$G17 -> 0 | R17: =O17/$G17 -> 0 | S17: 0 | T17: 0 | U17: =IFERROR(IF((T17/S17)>=1,100%,(T17/S17)),0%) -> 0 | V17: =N17+S17 -> 0 | W17: =O17+T17 -> 0 | X17: =W17-V17 -> 0 | Y17: =V17/$G17 -> 0 | Z17: =W17/$G17 -> 0 | AA17: 0 | AB17: 0 | AC17: =IFERROR(IF((AB17/AA17)>=1,100%,(AB17/AA17)),0%) -> 0 | AD17: =V17+AA17 -> 0 | AE17: =W17+AB17 -> 0 | AF17: =AE17-AD17 -> 0 | AG17: =AD17/$G17 -> 0 | AH17: =AE17/$G17 -> 0 | AI17: 0 | AJ17: 0 | AK17: =IFERROR(IF((AJ17/AI17)>=1,100%,(AJ17/AI17)),0%) -> 0 | AL17: =AD17+AI17 -> 0 | AM17: =AE17+AJ17 -> 0 | AN17: =AM17-AL17 -> 0 | AO17: =AL17/$G17 -> 0 | AP17: =AM17/$G17 -> 0 | AQ17: 0 | AR17: 0 | AS17: =IFERROR(IF((AR17/AQ17)>=1,100%,(AR17/AQ17)),0%) -> 0 | AT17: =AL17+AQ17 -> 0 | AU17: =AM17+AR17 -> 0 | AV17: =AU17-AT17 -> 0 | AW17: =AT17/$G17 -> 0 | AX17: =AU17/$G17 -> 0 | AY17: 0 | AZ17: 0 | BA17: =IFERROR(IF((AZ17/AY17)>=1,100%,(AZ17/AY17)),0%) -> 0 | BB17: =AT17+AY17 -> 0 | BC17: =AU17+AZ17 -> 0 | BD17: =BC17-BB17 -> 0 | BE17: =BB17/$G17 -> 0 | BF17: =BC17/$G17 -> 0 | BG17: 0 | BH17: 0 | BI17: =IFERROR(IF((BH17/BG17)>=1,100%,(BH17/BG17)),0%) -> 0 | BJ17: =BB17+BG17 -> 0 | BK17: =BC17+BH17 -> 0 | BL17: =BK17-BJ17 -> 0 | BM17: =BJ17/$G17 -> 0 | BN17: =BK17/$G17 -> 0 | BO17: 0 | BP17: 0 | BQ17: =IFERROR(IF((BP17/BO17)>=1,100%,(BP17/BO17)),0%) -> 0 | BR17: =BJ17+BO17 -> 0 | BS17: =BK17+BP17 -> 0 | BT17: =BS17-BR17 -> 0 | BU17: =BR17/$G17 -> 0 | BV17: =BS17/$G17 -> 0 | BW17: 0 | BX17: 0 | BY17: =IFERROR(IF((BX17/BW17)>=1,100%,(BX17/BW17)),0%) -> 0 | BZ17: =BR17+BW17 -> 0 | CA17: =BS17+BX17 -> 0 | CB17: =CA17-BZ17 -> 0 | CC17: =BZ17/$G17 -> 0 | CD17: =CA17/$G17 -> 0 | CE17: 0 | CF17: 0 | CG17: =IFERROR(IF((CF17/CE17)>=1,100%,(CF17/CE17)),0%) -> 0 | CH17: =BZ17+CE17 -> 0 | CI17: =CA17+CF17 -> 0 | CJ17: =CI17-CH17 -> 0 | CK17: =CH17/$G17 -> 0 | CL17: =CI17/$G17 -> 0 | CM17: 0 | CN17: 0 | CO17: =IFERROR(IF((CN17/CM17)>=1,100%,(CN17/CM17)),0%) -> 0 | CP17: =CH17+CM17 -> 0 | CQ17: =CI17+CN17 -> 0 | CR17: =CQ17-CP17 -> 0 | CS17: =CP17/$G17 -> 0 | CT17: =CQ17/$G17 -> 0 | CU17: 0 | CV17: 0 | CW17: =IFERROR(IF((CV17/CU17)>=1,100%,(CV17/CU17)),0%) -> 0 | CX17: =CP17+CU17 -> 0 | CY17: =CQ17+CV17 -> 0 | CZ17: =CY17-CX17 -> 0 | DA17: =CX17/$G17 -> 0 | DB17: =CY17/$G17 -> 0 | DC17: 0 | DD17: 0 | DE17: 0 | DF17: =CX17+DC17 -> 0 | DG17: =CY17+DD17 -> 0 | DH17: =DG17-DF17 -> 0 | DI17: =DF17/$G17 -> 0 | DJ17: =DG17/$G17 -> 0 | DK17: 0 | DL17: 0 | DM17: =IFERROR(IF((DL17/DK17)>=1,100%,(DL17/DK17)),0%) -> 0 | DN17: =DF17+DK17 -> 0 | DO17: =DG17+DL17 -> 0 | DP17: =DO17-DN17 -> 0 | DQ17: =DN17/$G17 -> 0 | DR17: =DO17/$G17 -> 0
F18: 구현 | G18: 1 | H18: 1 | I18: =SUM(L18+T18+AB18+AJ18+AR18+AZ18+BH18+BP18+BX18+CF18+CN18+CV18+DD18+DL18+DT18+EB18+EJ18+ER18+EZ18+FI18+FR18+GB18+GL18+GV18+HF18+HP18+HZ18+IJ18+IT18+JD18+JN18+JX18+KH18+KR18+LB18+LL18+LV18+MF18+MP18+MZ18) -> 0 | J18: =IFERROR(IF((I18/H18)>=1,100%,(I18/H18)),0%) -> 0 | K18: 0 | L18: 0 | M18: =IFERROR(IF((L18/K18)>=1,100%,(L18/K18)),0%) -> 0 | N18: =+K18 -> 0 | O18: =+L18 -> 0 | P18: =O18-N18 -> 0 | Q18: =N18/$G18 -> 0 | R18: =O18/$G18 -> 0 | S18: 0 | T18: 0 | U18: =IFERROR(IF((T18/S18)>=1,100%,(T18/S18)),0%) -> 0 | V18: =N18+S18 -> 0 | W18: =O18+T18 -> 0 | X18: =W18-V18 -> 0 | Y18: =V18/$G18 -> 0 | Z18: =W18/$G18 -> 0 | AA18: 0 | AB18: 0 | AC18: =IFERROR(IF((AB18/AA18)>=1,100%,(AB18/AA18)),0%) -> 0 | AD18: =V18+AA18 -> 0 | AE18: =W18+AB18 -> 0 | AF18: =AE18-AD18 -> 0 | AG18: =AD18/$G18 -> 0 | AH18: =AE18/$G18 -> 0 | AI18: 0 | AJ18: 0 | AK18: =IFERROR(IF((AJ18/AI18)>=1,100%,(AJ18/AI18)),0%) -> 0 | AL18: =AD18+AI18 -> 0 | AM18: =AE18+AJ18 -> 0 | AN18: =AM18-AL18 -> 0 | AO18: =AL18/$G18 -> 0 | AP18: =AM18/$G18 -> 0 | AQ18: 0 | AR18: 0 | AS18: =IFERROR(IF((AR18/AQ18)>=1,100%,(AR18/AQ18)),0%) -> 0 | AT18: =AL18+AQ18 -> 0 | AU18: =AM18+AR18 -> 0 | AV18: =AU18-AT18 -> 0 | AW18: =AT18/$G18 -> 0 | AX18: =AU18/$G18 -> 0 | AY18: 0 | AZ18: 0 | BA18: =IFERROR(IF((AZ18/AY18)>=1,100%,(AZ18/AY18)),0%) -> 0 | BB18: =AT18+AY18 -> 0 | BC18: =AU18+AZ18 -> 0 | BD18: =BC18-BB18 -> 0 | BE18: =BB18/$G18 -> 0 | BF18: =BC18/$G18 -> 0 | BG18: 0 | BH18: 0 | BI18: =IFERROR(IF((BH18/BG18)>=1,100%,(BH18/BG18)),0%) -> 0 | BJ18: =BB18+BG18 -> 0 | BK18: =BC18+BH18 -> 0 | BL18: =BK18-BJ18 -> 0 | BM18: =BJ18/$G18 -> 0 | BN18: =BK18/$G18 -> 0 | BO18: 0 | BP18: 0 | BQ18: =IFERROR(IF((BP18/BO18)>=1,100%,(BP18/BO18)),0%) -> 0 | BR18: =BJ18+BO18 -> 0 | BS18: =BK18+BP18 -> 0 | BT18: =BS18-BR18 -> 0 | BU18: =BR18/$G18 -> 0 | BV18: =BS18/$G18 -> 0 | BW18: 0 | BX18: 0 | BY18: =IFERROR(IF((BX18/BW18)>=1,100%,(BX18/BW18)),0%) -> 0 | BZ18: =BR18+BW18 -> 0 | CA18: =BS18+BX18 -> 0 | CB18: =CA18-BZ18 -> 0 | CC18: =BZ18/$G18 -> 0 | CD18: =CA18/$G18 -> 0 | CE18: 0 | CF18: 0 | CG18: =IFERROR(IF((CF18/CE18)>=1,100%,(CF18/CE18)),0%) -> 0 | CH18: =BZ18+CE18 -> 0 | CI18: =CA18+CF18 -> 0 | CJ18: =CI18-CH18 -> 0 | CK18: =CH18/$G18 -> 0 | CL18: =CI18/$G18 -> 0 | CM18: 0 | CN18: 0 | CO18: =IFERROR(IF((CN18/CM18)>=1,100%,(CN18/CM18)),0%) -> 0 | CP18: =CH18+CM18 -> 0 | CQ18: =CI18+CN18 -> 0 | CR18: =CQ18-CP18 -> 0 | CS18: =CP18/$G18 -> 0 | CT18: =CQ18/$G18 -> 0 | CU18: 0 | CV18: 0 | CW18: =IFERROR(IF((CV18/CU18)>=1,100%,(CV18/CU18)),0%) -> 0 | CX18: =CP18+CU18 -> 0 | CY18: =CQ18+CV18 -> 0 | CZ18: =CY18-CX18 -> 0 | DA18: =CX18/$G18 -> 0 | DB18: =CY18/$G18 -> 0 | DC18: 0 | DD18: 0 | DE18: 0 | DF18: =CX18+DC18 -> 0 | DG18: =CY18+DD18 -> 0 | DH18: =DG18-DF18 -> 0 | DI18: =DF18/$G18 -> 0 | DJ18: =DG18/$G18 -> 0 | DK18: 0 | DL18: 0 | DM18: =IFERROR(IF((DL18/DK18)>=1,100%,(DL18/DK18)),0%) -> 0 | DN18: =DF18+DK18 -> 0 | DO18: =DG18+DL18 -> 0 | DP18: =DO18-DN18 -> 0 | DQ18: =DN18/$G18 -> 0 | DR18: =DO18/$G18 -> 0
F19: 테스트 | G19: 1 | H19: 1 | I19: =SUM(L19+T19+AB19+AJ19+AR19+AZ19+BH19+BP19+BX19+CF19+CN19+CV19+DD19+DL19+DT19+EB19+EJ19+ER19+EZ19+FI19+FR19+GB19+GL19+GV19+HF19+HP19+HZ19+IJ19+IT19+JD19+JN19+JX19+KH19+KR19+LB19+LL19+LV19+MF19+MP19+MZ19) -> 0 | J19: =IFERROR(IF((I19/H19)>=1,100%,(I19/H19)),0%) -> 0 | K19: 0 | L19: 0 | M19: =IFERROR(IF((L19/K19)>=1,100%,(L19/K19)),0%) -> 0 | N19: =+K19 -> 0 | O19: =+L19 -> 0 | P19: =O19-N19 -> 0 | Q19: =N19/$G19 -> 0 | R19: =O19/$G19 -> 0 | S19: 0 | T19: 0 | U19: =IFERROR(IF((T19/S19)>=1,100%,(T19/S19)),0%) -> 0 | V19: =N19+S19 -> 0 | W19: =O19+T19 -> 0 | X19: =W19-V19 -> 0 | Y19: =V19/$G19 -> 0 | Z19: =W19/$G19 -> 0 | AA19: 0 | AB19: 0 | AC19: =IFERROR(IF((AB19/AA19)>=1,100%,(AB19/AA19)),0%) -> 0 | AD19: =V19+AA19 -> 0 | AE19: =W19+AB19 -> 0 | AF19: =AE19-AD19 -> 0 | AG19: =AD19/$G19 -> 0 | AH19: =AE19/$G19 -> 0 | AI19: 0 | AJ19: 0 | AK19: =IFERROR(IF((AJ19/AI19)>=1,100%,(AJ19/AI19)),0%) -> 0 | AL19: =AD19+AI19 -> 0 | AM19: =AE19+AJ19 -> 0 | AN19: =AM19-AL19 -> 0 | AO19: =AL19/$G19 -> 0 | AP19: =AM19/$G19 -> 0 | AQ19: 0 | AR19: 0 | AS19: =IFERROR(IF((AR19/AQ19)>=1,100%,(AR19/AQ19)),0%) -> 0 | AT19: =AL19+AQ19 -> 0 | AU19: =AM19+AR19 -> 0 | AV19: =AU19-AT19 -> 0 | AW19: =AT19/$G19 -> 0 | AX19: =AU19/$G19 -> 0 | AY19: 0 | AZ19: 0 | BA19: =IFERROR(IF((AZ19/AY19)>=1,100%,(AZ19/AY19)),0%) -> 0 | BB19: =AT19+AY19 -> 0 | BC19: =AU19+AZ19 -> 0 | BD19: =BC19-BB19 -> 0 | BE19: =BB19/$G19 -> 0 | BF19: =BC19/$G19 -> 0 | BG19: 0 | BH19: 0 | BI19: =IFERROR(IF((BH19/BG19)>=1,100%,(BH19/BG19)),0%) -> 0 | BJ19: =BB19+BG19 -> 0 | BK19: =BC19+BH19 -> 0 | BL19: =BK19-BJ19 -> 0 | BM19: =BJ19/$G19 -> 0 | BN19: =BK19/$G19 -> 0 | BO19: 0 | BP19: 0 | BQ19: =IFERROR(IF((BP19/BO19)>=1,100%,(BP19/BO19)),0%) -> 0 | BR19: =BJ19+BO19 -> 0 | BS19: =BK19+BP19 -> 0 | BT19: =BS19-BR19 -> 0 | BU19: =BR19/$G19 -> 0 | BV19: =BS19/$G19 -> 0 | BW19: 0 | BX19: 0 | BY19: =IFERROR(IF((BX19/BW19)>=1,100%,(BX19/BW19)),0%) -> 0 | BZ19: =BR19+BW19 -> 0 | CA19: =BS19+BX19 -> 0 | CB19: =CA19-BZ19 -> 0 | CC19: =BZ19/$G19 -> 0 | CD19: =CA19/$G19 -> 0 | CE19: 0 | CF19: 0 | CG19: =IFERROR(IF((CF19/CE19)>=1,100%,(CF19/CE19)),0%) -> 0 | CH19: =BZ19+CE19 -> 0 | CI19: =CA19+CF19 -> 0 | CJ19: =CI19-CH19 -> 0 | CK19: =CH19/$G19 -> 0 | CL19: =CI19/$G19 -> 0 | CM19: 0 | CN19: 0 | CO19: =IFERROR(IF((CN19/CM19)>=1,100%,(CN19/CM19)),0%) -> 0 | CP19: =CH19+CM19 -> 0 | CQ19: =CI19+CN19 -> 0 | CR19: =CQ19-CP19 -> 0 | CS19: =CP19/$G19 -> 0 | CT19: =CQ19/$G19 -> 0 | CU19: 0 | CV19: 0 | CW19: =IFERROR(IF((CV19/CU19)>=1,100%,(CV19/CU19)),0%) -> 0 | CX19: =CP19+CU19 -> 0 | CY19: =CQ19+CV19 -> 0 | CZ19: =CY19-CX19 -> 0 | DA19: =CX19/$G19 -> 0 | DB19: =CY19/$G19 -> 0 | DC19: 0 | DD19: 0 | DE19: 0 | DF19: =CX19+DC19 -> 0 | DG19: =CY19+DD19 -> 0 | DH19: =DG19-DF19 -> 0 | DI19: =DF19/$G19 -> 0 | DJ19: =DG19/$G19 -> 0 | DK19: 0 | DL19: 0 | DM19: =IFERROR(IF((DL19/DK19)>=1,100%,(DL19/DK19)),0%) -> 0 | DN19: =DF19+DK19 -> 0 | DO19: =DG19+DL19 -> 0 | DP19: =DO19-DN19 -> 0 | DQ19: =DN19/$G19 -> 0 | DR19: =DO19/$G19 -> 0
